Workbook

Sheet Новости
A1: Единый реестр новостей муниципалитетов Республики Коми
A2: Одна публикация = одна строка. Основной муниципалитет обязателен; дополнительные перечисляйте через ;. Региональную новость вносить только при явной связи с муниципалитетом. Рабочий период — последние 30 дней; старые строки не удалять.
A3: Обязательное
A5: Сборщик | B5: Дата сбора | C5: Основной муниципалитет | D5: Дополнительные муниципалитеты | E5: Дата публикации | F5: Дата события | G5: Источник | H5: Прямая ссылка | I5: Дополнительные ссылки | J5: Заголовок | K5: Категория | L5: Стадия события | M5: Краткое фактическое резюме | N5: Ключевые цифры и факты | O5: Упомянутые лица | P5: Организации | Q5: ИНН из источника | R5: Объект/населённый пункт | S5: Возможный дубль | T5: Комментарий | U5: Автопроверка
A6: Python parser | B6: 2026-09-23 | C6: Республика Коми | E6: 2026-09-09 | G6: Государственный Совет Республики Коми | H6: https://www.gsrk.ru/presscenter/news/85584/ | J6: Александр Макаренко обсудил с Мариной Ким вопросы защиты пенсионных прав северян | K6: Власть и кадровые решения | L6: Встреча | M6: Александр Макаренко провел рабочую встречу с Мариной Ким для обсуждения вопросов защиты пенсионных прав северян и законодательных инициатив Республики Коми. | O6: Александр Макаренко, Марина Ким | P6: Государственный Совет Республики Коми, Комитет Государственной Думы по информационной политике, информационным технологиям и связи | R6: Сыктывкар | U6: =IF(COUNTA(A6:T6)=0,"",IF(OR(A6="",B6="",C6="",E6="",G6="",H6="",J6="",K6="",L6="",M6=""),"Ошибка: заполните обязательные поля",IF(AND(LEFT(H6,7)<>"http://",LEFT(H6,8)<>"https://"),"Ошибка: некорректная ссылка",IF(COUNTIF($H$6:$H$1005,H6)>1,"Ошибка: дубликат URL",IF(E6>TODAY(),"Ошибка: дата публикации в будущем",IF(S6="Да","Ошибка: подтверждённый дубль",IF(S6="","Проверить: отметьте дубль",IF(S6="Нужно проверить","Проверить возможный дубль",IF(TODAY()-E6>30,"Проверить: старше 30 дней",IF(COUNTIFS(#REF!,G6,#REF!,"Готово")=0,"Проверить источник","Готово"))))))))))
A7: Python parser | B7: 2026-09-23 | C7: Республика Коми | E7: 2026-09-09 | G7: Государственный Совет Республики Коми | H7: https://www.gsrk.ru/presscenter/news/85578/ | J7: Государственный Совет Коми стал площадкой для федерального диалога бизнеса и власти | K7: Экономика, бизнес и занятость | L7: Решение принято | M7: В Сыктывкаре прошёл форум предпринимателей с участием главы Коми и президента РСПП, где обсуждались вопросы поддержки деловой активности в условиях Севера и Арктики. | N7: Выдано микрозаймов на 2 млрд рублей; поручительства фонда на 3,5 млрд привлекли 9 млрд кредитных средств. | O7: Ростислав Гольдштейн (Глава Республики Коми), Александр Шохин (президент РСПП) | P7: Государственный Совет Республики Коми, Российский союз промышленников и предпринимателей | R7: Сыктывкар | U7: =IF(COUNTA(A7:T7)=0,"",IF(OR(A7="",B7="",C7="",E7="",G7="",H7="",J7="",K7="",L7="",M7=""),"Ошибка: заполните обязательные поля",IF(AND(LEFT(H7,7)<>"http://",LEFT(H7,8)<>"https://"),"Ошибка: некорректная ссылка",IF(COUNTIF($H$6:$H$1005,H7)>1,"Ошибка: дубликат URL",IF(E7>TODAY(),"Ошибка: дата публикации в будущем",IF(S7="Да","Ошибка: подтверждённый дубль",IF(S7="","Проверить: отметьте дубль",IF(S7="Нужно проверить","Проверить возможный дубль",IF(TODAY()-E7>30,"Проверить: старше 30 дней",IF(COUNTIFS(#REF!,G7,#REF!,"Готово")=0,"Проверить источник","Готово"))))))))))
A8: Python parser | B8: 2026-09-23 | C8: Республика Коми | E8: 2026-09-07 | G8: Государственный Совет Республики Коми | H8: https://www.gsrk.ru/presscenter/news/85462/ | J8: Александр Макаренко: «Качественная спортивная инфраструктура в районах — это основа здоровья наших граждан» | K8: Строительство и инфраструктура | L8: Работы начаты | M8: Руководство Республики Коми провело инспекцию строительства и модернизации спортивных объектов в Усть-Вымском районе, включая завершение возведения модульного спортивного зала в селе Айкино и капитальный ремонт Центра спорта и туризма в городе Микунь. | N8: Модульный спортивный зал в селе Айкино готов на 94%, ремонт Центра спорта и туризма в городе Микунь выполнен на 50%; подрядчики ООО «Каркас» и ООО «Исток»; финансирование осуществляется через соглашение о социальном партнерстве с компанией «ЛУКОЙЛ». | O8: Ростислав Гольдштейн (Глава Республики Коми), Александр Макаренко (Председатель Государственного Совета Республики Коми) | P8: ООО «Каркас», ООО «Исток», Правительство Коми, компания «ЛУКОЙЛ» | R8: Усть-Вымский район, село Айкино, город Микунь | U8: =IF(COUNTA(A8:T8)=0,"",IF(OR(A8="",B8="",C8="",E8="",G8="",H8="",J8="",K8="",L8="",M8=""),"Ошибка: заполните обязательные поля",IF(AND(LEFT(H8,7)<>"http://",LEFT(H8,8)<>"https://"),"Ошибка: некорректная ссылка",IF(COUNTIF($H$6:$H$1005,H8)>1,"Ошибка: дубликат URL",IF(E8>TODAY(),"Ошибка: дата публикации в будущем",IF(S8="Да","Ошибка: подтверждённый дубль",IF(S8="","Проверить: отметьте дубль",IF(S8="Нужно проверить","Проверить возможный дубль",IF(TODAY()-E8>30,"Проверить: старше 30 дней",IF(COUNTIFS(#REF!,G8,#REF!,"Готово")=0,"Проверить источник","Готово"))))))))))
A9: Python parser | B9: 2026-09-23 | C9: Республика Коми | E9: 2026-09-07 | G9: Государственный Совет Республики Коми | H9: https://www.gsrk.ru/presscenter/news/85461/ | J9: В Ухте открыли современный "Газпром-парк" площадью 10 гектаров | K9: Строительство и инфраструктура | L9: Завершено / открыто | M9: В Ухте открылся новый общественный парк 'Газпром-парк' площадью 10 гектаров, созданный на средства ПАО 'Газпром', включающий дорожки для прогулок, спортивные и детские площадки. | N9: Площадь парка - 10 гектаров; длина дорожек - более 6 км; наличие спортивных площадок для волейбола, бадминтона, настольного тенниса, скейт-парка и детских игровых зон; возможность зимнего катания на лыжах и коньках. | O9: Ростислав Гольдштейн (Глава Республики Коми), Александр Макаренко (Председатель Государственного Совета Республики Коми), Станислав Кочев (вице-спикер, Герой России), Владимир Блохин (депутат регионального парламента) | P9: ПАО 'Газпром' | R9: Ухта | U9: =IF(COUNTA(A9:T9)=0,"",IF(OR(A9="",B9="",C9="",E9="",G9="",H9="",J9="",K9="",L9="",M9=""),"Ошибка: заполните обязательные поля",IF(AND(LEFT(H9,7)<>"http://",LEFT(H9,8)<>"https://"),"Ошибка: некорректная ссылка",IF(COUNTIF($H$6:$H$1005,H9)>1,"Ошибка: дубликат URL",IF(E9>TODAY(),"Ошибка: дата публикации в будущем",IF(S9="Да","Ошибка: подтверждённый дубль",IF(S9="","Проверить: отметьте дубль",IF(S9="Нужно проверить","Проверить возможный дубль",IF(TODAY()-E9>30,"Проверить: старше 30 дней",IF(COUNTIFS(#REF!,G9,#REF!,"Готово")=0,"Проверить источник","Готово"))))))))))
A10: Python parser | B10: 2026-09-23 | C10: Республика Коми | E10: 2026-09-10 | G10: БНК | H10: https://www.bnkomi.ru/data/news/203119/ | J10: Малотравматичная операция новорожденному в РДКБ Коми | K10: Здравоохранение | L10: Результат | M10: В Республике Коми успешно проведена сложная малотравматичная операция новорожденному с опухолью надпочечника. Благодаря современному оборудованию и высокой квалификации врачей, вмешательство прошло успешно и минимально травматично для маленького пациента. | N10: 3,5-4 см | O10: Руслан Ислентьев, главный детский хирург Минздрава Коми, заместитель главного врача по хирургии РДКБ | P10: Республиканская детская клиническая больница | Q10: - | R10: Республика Коми | U10: =IF(COUNTA(A10:T10)=0,"",IF(OR(A10="",B10="",C10="",E10="",G10="",H10="",J10="",K10="",L10="",M10=""),"Ошибка: заполните обязательные поля",IF(AND(LEFT(H10,7)<>"http://",LEFT(H10,8)<>"https://"),"Ошибка: некорректная ссылка",IF(COUNTIF($H$6:$H$1005,H10)>1,"Ошибка: дубликат URL",IF(E10>TODAY(),"Ошибка: дата публикации в будущем",IF(S10="Да","Ошибка: подтверждённый дубль",IF(S10="","Проверить: отметьте дубль",IF(S10="Нужно проверить","Проверить возможный дубль",IF(TODAY()-E10>30,"Проверить: старше 30 дней",IF(COUNTIFS(#REF!,G10,#REF!,"Готово")=0,"Проверить источник","Готово"))))))))))
A11: Python parser | B11: 2026-09-23 | C11: Республика Коми | E11: 2026-09-10 | G11: БНК | H11: https://www.bnkomi.ru/data/news/203120/ | J11: Шохин обсудил поддержку инвестиций в Коми | K11: Экономика, бизнес и занятость | L11: Анонс | M11: Президент Российского союза промышленников и предпринимателей Александр Шохин посетил Республику Коми, где провел переговоры о поддержке инвестиционных проектов и мерах по стимулированию промышленного сектора в проекте бюджета на ближайшие годы. | N11: - | O11: Александр Шохин, президент Российского союза промышленников и предпринимателей; Ростислав Гольдштейн, глава Республики Коми | P11: Российский союз промышленников и предпринимателей, Коми союз промышленников и предпринимателей, ООО «Лузалес», ООО «Кофе плюс», Правительство Республики Коми, Минпромторг, Министерство экономического развития | Q11: - | R11: Сыктывкар, Республика Коми | U11: =IF(COUNTA(A11:T11)=0,"",IF(OR(A11="",B11="",C11="",E11="",G11="",H11="",J11="",K11="",L11="",M11=""),"Ошибка: заполните обязательные поля",IF(AND(LEFT(H11,7)<>"http://",LEFT(H11,8)<>"https://"),"Ошибка: некорректная ссылка",IF(COUNTIF($H$6:$H$1005,H11)>1,"Ошибка: дубликат URL",IF(E11>TODAY(),"Ошибка: дата публикации в будущем",IF(S11="Да","Ошибка: подтверждённый дубль",IF(S11="","Проверить: отметьте дубль",IF(S11="Нужно проверить","Проверить возможный дубль",IF(TODAY()-E11>30,"Проверить: старше 30 дней",IF(COUNTIFS(#REF!,G11,#REF!,"Готово")=0,"Проверить источник","Готово"))))))))))
A12: Python parser | B12: 2026-09-23 | C12: Республика Коми | E12: 2026-09-10 | G12: БНК | H12: https://www.bnkomi.ru/data/news/203121/ | J12: Поддержка семей в Республике Коми увеличивает рождаемость | K12: Социальная сфера | L12: Результат | M12: В рамках круглого стола обсуждалась эффективность мер поддержки семей с детьми в Республике Коми. Министр труда и соцзащиты Татьяна Майкова сообщила о положительной динамике рождаемости благодаря мерам государственной помощи, таких как семейный капитал и дополнительные выплаты. | N12: 37% (доля первенцев), 29% (прошлый показатель доли первенцев), 1,5 тыс. (прирост многодетных семей за 5 лет), 12 тыс. (число многодетных семей сейчас), 41 тыс. (дети в многодетных семьях) | O12: Татьяна Майкова (Министр труда и социальной защиты Республики Коми) | P12: - | Q12: - | R12: Сыктывкар | U12: =IF(COUNTA(A12:T12)=0,"",IF(OR(A12="",B12="",C12="",E12="",G12="",H12="",J12="",K12="",L12="",M12=""),"Ошибка: заполните обязательные поля",IF(AND(LEFT(H12,7)<>"http://",LEFT(H12,8)<>"https://"),"Ошибка: некорректная ссылка",IF(COUNTIF($H$6:$H$1005,H12)>1,"Ошибка: дубликат URL",IF(E12>TODAY(),"Ошибка: дата публикации в будущем",IF(S12="Да","Ошибка: подтверждённый дубль",IF(S12="","Проверить: отметьте дубль",IF(S12="Нужно проверить","Проверить возможный дубль",IF(TODAY()-E12>30,"Проверить: старше 30 дней",IF(COUNTIFS(#REF!,G12,#REF!,"Готово")=0,"Проверить источник","Готово"))))))))))
A13: Python parser | B13: 2026-09-23 | C13: Республика Коми | E13: 2026-09-10 | G13: БНК | H13: https://www.bnkomi.ru/data/news/196391/ | J13: Проект "Подарок новорожденному" в Республике Коми | K13: Социальная сфера | L13: В процессе | M13: Министерство труда и социальной защиты Республики Коми реализует проект "Подарок новорожденному", предоставляя наборы для младенцев. В комплект входит 19 предметов первой необходимости. На 2026 год выделен бюджет в размере 36,285 млн рублей. | N13: 5861 комплект в 2025 г., 812 комплектов за январь-февраль 2026 г., 36,285 млн руб. budget на 2026 г. | O13: - | P13: Министерство труда и социальной защиты Коми | Q13: - | R13: Республика Коми | U13: =IF(COUNTA(A13:T13)=0,"",IF(OR(A13="",B13="",C13="",E13="",G13="",H13="",J13="",K13="",L13="",M13=""),"Ошибка: заполните обязательные поля",IF(AND(LEFT(H13,7)<>"http://",LEFT(H13,8)<>"https://"),"Ошибка: некорректная ссылка",IF(COUNTIF($H$6:$H$1005,H13)>1,"Ошибка: дубликат URL",IF(E13>TODAY(),"Ошибка: дата публикации в будущем",IF(S13="Да","Ошибка: подтверждённый дубль",IF(S13="","Проверить: отметьте дубль",IF(S13="Нужно проверить","Проверить возможный дубль",IF(TODAY()-E13>30,"Проверить: старше 30 дней",IF(COUNTIFS(#REF!,G13,#REF!,"Готово")=0,"Проверить источник","Готово"))))))))))
A14: Python parser | B14: 2026-09-23 | C14: Республика Коми | E14: 2026-09-10 | G14: БНК | H14: https://www.bnkomi.ru/data/news/203127/ | J14: Перспективы нацгорного кластера в Коми обсудили с Александром Шохиным | K14: Экономика, бизнес и занятость | L14: Анонс | M14: Александр Шохин обсудил с руководством Коми инвестиционные проекты, включая создание национального горнопромышленного кластера на основе Пижемского месторождения титана и кварца. Проект реализуется компанией ГК «РУСТИТАН» при поддержке ведущих научных институтов России. | N14: - | O14: Александр Шохин, Ростислав Гольдштейн | P14: Российский союз промышленников и предпринимателей, ГК «РУСТИТАН», Институт металлургии и материаловедения им. А.А. Байкова Российской академии наук, Институт геологии рудных месторождений, петрографии, минералогии и геохимии Российской академии наук | Q14: - | R14: Республика Коми | U14: =IF(COUNTA(A14:T14)=0,"",IF(OR(A14="",B14="",C14="",E14="",G14="",H14="",J14="",K14="",L14="",M14=""),"Ошибка: заполните обязательные поля",IF(AND(LEFT(H14,7)<>"http://",LEFT(H14,8)<>"https://"),"Ошибка: некорректная ссылка",IF(COUNTIF($H$6:$H$1005,H14)>1,"Ошибка: дубликат URL",IF(E14>TODAY(),"Ошибка: дата публикации в будущем",IF(S14="Да","Ошибка: подтверждённый дубль",IF(S14="","Проверить: отметьте дубль",IF(S14="Нужно проверить","Проверить возможный дубль",IF(TODAY()-E14>30,"Проверить: старше 30 дней",IF(COUNTIFS(#REF!,G14,#REF!,"Готово")=0,"Проверить источник","Готово"))))))))))
A15: Python parser | B15: 2026-09-23 | C15: Республика Коми | E15: 2026-09-10 | G15: БНК | H15: https://www.bnkomi.ru/data/news/203128/ | J15: Развитие Северного морского пути обсудили в Сыктывкаре | K15: Экономика, бизнес и занятость | L15: Анонс | M15: Официальный представитель МИД России Мария Захарова обсудила перспективы развития Северного морского пути на выездном брифинге в Сыктывкаре. Она подчеркнула важность освоения Арктики и Северного морского пути для экономики и безопасности страны, отметив растущий интерес зарубежных партнеров к сотрудничеству в этой области. | N15: - | O15: Мария Захарова, Владимир Путин | P15: МИД России | Q15: - | R15: Республика Коми | U15: =IF(COUNTA(A15:T15)=0,"",IF(OR(A15="",B15="",C15="",E15="",G15="",H15="",J15="",K15="",L15="",M15=""),"Ошибка: заполните обязательные поля",IF(AND(LEFT(H15,7)<>"http://",LEFT(H15,8)<>"https://"),"Ошибка: некорректная ссылка",IF(COUNTIF($H$6:$H$1005,H15)>1,"Ошибка: дубликат URL",IF(E15>TODAY(),"Ошибка: дата публикации в будущем",IF(S15="Да","Ошибка: подтверждённый дубль",IF(S15="","Проверить: отметьте дубль",IF(S15="Нужно проверить","Проверить возможный дубль",IF(TODAY()-E15>30,"Проверить: старше 30 дней",IF(COUNTIFS(#REF!,G15,#REF!,"Готово")=0,"Проверить источник","Готово"))))))))))
A16: Python parser | B16: 2026-09-23 | C16: Республика Коми | E16: 2026-09-10 | G16: БНК | H16: https://www.bnkomi.ru/data/news/203129/ | J16: Ростислав Гольдштейн проведет прямую линию с жителями Коми | K16: Управление | L16: Анонс | M16: Сегодня в 18:00 Ростислав Гольдштейн ответит на вопросы жителей Республики Коми в прямом эфире. Колл-центр принимает вопросы по темам ЖКХ, благоустройства и дорог с использованием новой федеральной платформы обратной связи, что обеспечивает отслеживание всех обращений до их разрешения. | N16: - | O16: Ростислав Гольдштейн, Полина Разманова, Виталий Осипов | P16: Колл-центр, Министерство цифрового развития и связи Республики Коми, администрация главы и правительства Республики Коми | Q16: - | R16: Республика Коми | U16: =IF(COUNTA(A16:T16)=0,"",IF(OR(A16="",B16="",C16="",E16="",G16="",H16="",J16="",K16="",L16="",M16=""),"Ошибка: заполните обязательные поля",IF(AND(LEFT(H16,7)<>"http://",LEFT(H16,8)<>"https://"),"Ошибка: некорректная ссылка",IF(COUNTIF($H$6:$H$1005,H16)>1,"Ошибка: дубликат URL",IF(E16>TODAY(),"Ошибка: дата публикации в будущем",IF(S16="Да","Ошибка: подтверждённый дубль",IF(S16="","Проверить: отметьте дубль",IF(S16="Нужно проверить","Проверить возможный дубль",IF(TODAY()-E16>30,"Проверить: старше 30 дней",IF(COUNTIFS(#REF!,G16,#REF!,"Готово")=0,"Проверить источник","Готово"))))))))))
A17: Python parser | B17: 2026-09-23 | C17: Республика Коми | E17: 2026-09-10 | G17: БНК | H17: https://www.bnkomi.ru/data/news/203132/ | J17: Диалог Марии Захаровой о рисках конфликта в Арктике | K17: Власть и кадровые решения | L17: - | M17: Официальный представитель МИД России Мария Захарова заявила об усилении военной активности НАТО у северных границ страны и превращении Арктики в зону геополитической конфронтации. Она отметила, что Россия наблюдает за действиями альянса и готова принять необходимые меры для обеспечения своей безопасности, оставаясь при этом открытой для международного диалога. | N17: - | O17: Мария Захарова (официальный представитель МИД России) | P17: МИД России, НАТО, Минобороны России | Q17: - | R17: Арктика, Сыктывкар | U17: =IF(COUNTA(A17:T17)=0,"",IF(OR(A17="",B17="",C17="",E17="",G17="",H17="",J17="",K17="",L17="",M17=""),"Ошибка: заполните обязательные поля",IF(AND(LEFT(H17,7)<>"http://",LEFT(H17,8)<>"https://"),"Ошибка: некорректная ссылка",IF(COUNTIF($H$6:$H$1005,H17)>1,"Ошибка: дубликат URL",IF(E17>TODAY(),"Ошибка: дата публикации в будущем",IF(S17="Да","Ошибка: подтверждённый дубль",IF(S17="","Проверить: отметьте дубль",IF(S17="Нужно проверить","Проверить возможный дубль",IF(TODAY()-E17>30,"Проверить: старше 30 дней",IF(COUNTIFS(#REF!,G17,#REF!,"Готово")=0,"Проверить источник","Готово"))))))))))
A18: Python parser | B18: 2026-09-23 | C18: Воркута | E18: 2026-08-30 | G18: Воркута.Официально | H18: https://komiinform.ru/news/299815 | J18: Ростислав Гольдштейн поздравил шахтёров Воркуты с Днём шахтёра | K18: Власть и кадровые решения | L18: - | M18: Глава Республики Коми Ростислав Гольдштейн принял участие в праздновании Дня шахтёра в Воркуте, отметив вклад шахтеров в развитие региона и важность их работы для всей страны. Он также выразил благодарность жителям Воркуты за совместную работу по улучшению городской среды. | N18: - | O18: Ростислав Гольдштейн (Глава Республики Коми), Александр Макаренко (Председатель Государственного Совета Республики Коми) | P18: Государственный Совет Республики Коми | Q18: - | R18: Воркута | U18: =IF(COUNTA(A18:T18)=0,"",IF(OR(A18="",B18="",C18="",E18="",G18="",H18="",J18="",K18="",L18="",M18=""),"Ошибка: заполните обязательные поля",IF(AND(LEFT(H18,7)<>"http://",LEFT(H18,8)<>"https://"),"Ошибка: некорректная ссылка",IF(COUNTIF($H$6:$H$1005,H18)>1,"Ошибка: дубликат URL",IF(E18>TODAY(),"Ошибка: дата публикации в будущем",IF(S18="Да","Ошибка: подтверждённый дубль",IF(S18="","Проверить: отметьте дубль",IF(S18="Нужно проверить","Проверить возможный дубль",IF(TODAY()-E18>30,"Проверить: старше 30 дней",IF(COUNTIFS(#REF!,G18,#REF!,"Готово")=0,"Проверить источник","Готово"))))))))))
A19: Python parser | B19: 2026-09-23 | C19: Сыктывкар | E19: 2026-08-24 | G19: Максим Мартышин | H19: https://pos.gosuslugi.ru/lkp/direct-line/13583 | J19: Прямая линия с Главой Коми Гольдштейном | K19: Власть и кадровые решения | L19: В процессе | M19: Глава Республики Коми Ростислав Гольдштейн проводит прямую линию, принимает вопросы граждан от зарегистрированных пользователей ЕСИА. | N19: Дата начала: 24.08.2026 | O19: Гольдштейн Ростислав Эрнстович, Глава Республики Коми | P19: - | Q19: - | R19: Республика Коми | U19: =IF(COUNTA(A19:T19)=0,"",IF(OR(A19="",B19="",C19="",E19="",G19="",H19="",J19="",K19="",L19="",M19=""),"Ошибка: заполните обязательные поля",IF(AND(LEFT(H19,7)<>"http://",LEFT(H19,8)<>"https://"),"Ошибка: некорректная ссылка",IF(COUNTIF($H$6:$H$1005,H19)>1,"Ошибка: дубликат URL",IF(E19>TODAY(),"Ошибка: дата публикации в будущем",IF(S19="Да","Ошибка: подтверждённый дубль",IF(S19="","Проверить: отметьте дубль",IF(S19="Нужно проверить","Проверить возможный дубль",IF(TODAY()-E19>30,"Проверить: старше 30 дней",IF(COUNTIFS(#REF!,G19,#REF!,"Готово")=0,"Проверить источник","Готово"))))))))))
A20: Python parser | B20: 2026-09-23 | C20: Республика Коми | E20: 2026-09-10 | G20: Минобрнауки Коми | H20: http://fromkomi.ru/ | J20: Создание регионального бренда продуктов Коми | K20: Экономика, бизнес и занятость | L20: - | M20: В Республике Коми создается единый бренд для региональных продуктов питания, подчеркивающий их высокое качество, натуральность и местные традиции. | N20: - | O20: - | P20: - | Q20: - | R20: Республика Коми | U20: =IF(COUNTA(A20:T20)=0,"",IF(OR(A20="",B20="",C20="",E20="",G20="",H20="",J20="",K20="",L20="",M20=""),"Ошибка: заполните обязательные поля",IF(AND(LEFT(H20,7)<>"http://",LEFT(H20,8)<>"https://"),"Ошибка: некорректная ссылка",IF(COUNTIF($H$6:$H$1005,H20)>1,"Ошибка: дубликат URL",IF(E20>TODAY(),"Ошибка: дата публикации в будущем",IF(S20="Да","Ошибка: подтверждённый дубль",IF(S20="","Проверить: отметьте дубль",IF(S20="Нужно проверить","Проверить возможный дубль",IF(TODAY()-E20>30,"Проверить: старше 30 дней",IF(COUNTIFS(#REF!,G20,#REF!,"Готово")=0,"Проверить источник","Готово"))))))))))
A21: Python parser | B21: 2026-09-23 | C21: Республика Коми | E21: 2026-09-10 | G21: Минобрнауки Коми | H21: http://technogto.kruzhok.org/ | J21: Онлайн-марафон ТехноГТО 'Космическая квадрига' | K21: Образование | L21: Анонс | M21: В рамках проекта 'Таланты для космоса' пройдет онлайн-марафон ТехноГТО, где участники могут заработать дополнительные баллы к ЕГЭ и выиграть призы. Мероприятие рассчитано на школьников старших классов и студентов. | N21: 1 сентября 2026, 31 октября 2026, 10 дополнительных баллов | O21: - | P21: Проект 'Таланты для космоса' | Q21: - | R21: - | U21: =IF(COUNTA(A21:T21)=0,"",IF(OR(A21="",B21="",C21="",E21="",G21="",H21="",J21="",K21="",L21="",M21=""),"Ошибка: заполните обязательные поля",IF(AND(LEFT(H21,7)<>"http://",LEFT(H21,8)<>"https://"),"Ошибка: некорректная ссылка",IF(COUNTIF($H$6:$H$1005,H21)>1,"Ошибка: дубликат URL",IF(E21>TODAY(),"Ошибка: дата публикации в будущем",IF(S21="Да","Ошибка: подтверждённый дубль",IF(S21="","Проверить: отметьте дубль",IF(S21="Нужно проверить","Проверить возможный дубль",IF(TODAY()-E21>30,"Проверить: старше 30 дней",IF(COUNTIFS(#REF!,G21,#REF!,"Готово")=0,"Проверить источник","Готово"))))))))))
... A31: Python parser | B31: 2026-09-23 | C31: Республика Коми | E31: 2026-08-20 | G31: ГОЛОС РЕСПУБЛИКИ | H31: https://t.me/s/kompartya/14627 | J31: КПРФ в Республике Коми | K31: ВЫБОРЫ И ПАРТИИ | L31: - | M31: Новость касается деятельности Коммунистической партии Российской Федерации в Республике Коми. | N31: - | O31: - | P31: КПРФ | Q31: - | R31: Республика Коми | U31: =IF(COUNTA(A31:T31)=0,"",IF(OR(A31="",B31="",C31="",E31="",G31="",H31="",J31="",K31="",L31="",M31=""),"Ошибка: заполните обязательные поля",IF(AND(LEFT(H31,7)<>"http://",LEFT(H31,8)<>"https://"),"Ошибка: некорректная ссылка",IF(COUNTIF($H$6:$H$1005,H31)>1,"Ошибка: дубликат URL",IF(E31>TODAY(),"Ошибка: дата публикации в будущем",IF(S31="Да","Ошибка: подтверждённый дубль",IF(S31="","Проверить: отметьте дубль",IF(S31="Нужно проверить","Проверить возможный дубль",IF(TODAY()-E31>30,"Проверить: старше 30 дней",IF(COUNTIFS(#REF!,G31,#REF!,"Готово")=0,"Проверить источник","Готово"))))))))))
A32: Python parser | B32: 2026-09-23 | C32: Республика Коми | E32: 2026-09-03 | G32: Гольдштейн | Республика Коми | H32: https://t.me/s/goldshtein_komi | J32: Гольдштейн | Республика Коми | K32: Власть и кадровые решения | M32: Официальный Telegram-канал Главы Республики Коми Ростислава Гольдштейна. Актуальная информация о работе Правительства Республики Коми, решениях и событиях региона. Подписывайтесь, чтобы быть в курсе! Номер заявления для регистрации: 5955805962 | U32: =IF(COUNTA(A32:T32)=0,"",IF(OR(A32="",B32="",C32="",E32="",G32="",H32="",J32="",K32="",L32="",M32=""),"Ошибка: заполните обязательные поля",IF(AND(LEFT(H32,7)<>"http://",LEFT(H32,8)<>"https://"),"Ошибка: некорректная ссылка",IF(COUNTIF($H$6:$H$1005,H32)>1,"Ошибка: дубликат URL",IF(E32>TODAY(),"Ошибка: дата публикации в будущем",IF(S32="Да","Ошибка: подтверждённый дубль",IF(S32="","Проверить: отметьте дубль",IF(S32="Нужно проверить","Проверить возможный дубль",IF(TODAY()-E32>30,"Проверить: старше 30 дней",IF(COUNTIFS(#REF!,G32,#REF!,"Готово")=0,"Проверить источник","Готово"))))))))))
A33: Python parser | B33: 2026-09-23 | C33: Республика Коми | E33: 2026-09-08 | G33: Минэкономразвития и промышленности Республики Коми | H33: https://t.me/s/MinEcKomi | J33: Минэкономразвития и промышленности Республики Коми | K33: Экономика | M33: Офицальный канал Министерства экономического развития и промышленности Республики Коми Офицальный сайт: https://econom.rkomi.ru/ Вконтакте: https://vk.com/mineconomy11 | U33: =IF(COUNTA(A33:T33)=0,"",IF(OR(A33="",B33="",C33="",E33="",G33="",H33="",J33="",K33="",L33="",M33=""),"Ошибка: заполните обязательные поля",IF(AND(LEFT(H33,7)<>"http://",LEFT(H33,8)<>"https://"),"Ошибка: некорректная ссылка",IF(COUNTIF($H$6:$H$1005,H33)>1,"Ошибка: дубликат URL",IF(E33>TODAY(),"Ошибка: дата публикации в будущем",IF(S33="Да","Ошибка: подтверждённый дубль",IF(S33="","Проверить: отметьте дубль",IF(S33="Нужно проверить","Проверить возможный дубль",IF(TODAY()-E33>30,"Проверить: старше 30 дней",IF(COUNTIFS(#REF!,G33,#REF!,"Готово")=0,"Проверить источник","Готово"))))))))))
A34: Python parser | B34: 2026-09-23 | C34: Республика Коми | E34: 2026-09-04 | G34: Государственный Совет Республики Коми | H34: https://www.gsrk.ru/presscenter/news/85456/ | J34: Парламентские уроки в Коми посвятили теме единства и участию молодёжи в жизни республики | K34: Образование | L34: Решение принято | M34: Депутаты Государственного Совета Республики Коми провели парламентские уроки с молодежью, обсудив тему Года единства народов России и проект 'Команда Республики Коми', направленный на объединение активных граждан. | O34: Анастасия Михайлова (депутат, председатель Комитета по социальной политике), Ростислав Гольдштейн (Глава республики) | P34: Государственный Совет Республики Коми, Коми республиканский колледж культуры им. В.Т. Чисталева | R34: Республика Коми | U34: =IF(COUNTA(A34:T34)=0,"",IF(OR(A34="",B34="",C34="",E34="",G34="",H34="",J34="",K34="",L34="",M34=""),"Ошибка: заполните обязательные поля",IF(AND(LEFT(H34,7)<>"http://",LEFT(H34,8)<>"https://"),"Ошибка: некорректная ссылка",IF(COUNTIF($H$6:$H$1005,H34)>1,"Ошибка: дубликат URL",IF(E34>TODAY(),"Ошибка: дата публикации в будущем",IF(S34="Да","Ошибка: подтверждённый дубль",IF(S34="","Проверить: отметьте дубль",IF(S34="Нужно проверить","Проверить возможный дубль",IF(TODAY()-E34>30,"Проверить: старше 30 дней",IF(COUNTIFS(#REF!,G34,#REF!,"Готово")=0,"Проверить источник","Готово"))))))))))
A35: Python parser | B35: 2026-09-23 | C35: Республика Коми | E35: 2026-09-04 | G35: Государственный Совет Республики Коми | H35: https://www.gsrk.ru/presscenter/news/85430/ | J35: Александр Макаренко: Модернизация очистных сооружений в Микуни — результат совместной работы властей и контроля за запросами граждан | K35: Строительство и инфраструктура | L35: Завершено / открыто | M35: Завершилась модернизация очистных сооружений в городе Микунь, позволившая перейти на подземный водозабор, что улучшит качество питьевой воды. | O35: Александр Макаренко, Ростислав Гольдштейн | P35: Государственный Совет Республики Коми, Усть-Вымская тепловая компания | R35: Микунь | U35: =IF(COUNTA(A35:T35)=0,"",IF(OR(A35="",B35="",C35="",E35="",G35="",H35="",J35="",K35="",L35="",M35=""),"Ошибка: заполните обязательные поля",IF(AND(LEFT(H35,7)<>"http://",LEFT(H35,8)<>"https://"),"Ошибка: некорректная ссылка",IF(COUNTIF($H$6:$H$1005,H35)>1,"Ошибка: дубликат URL",IF(E35>TODAY(),"Ошибка: дата публикации в будущем",IF(S35="Да","Ошибка: подтверждённый дубль",IF(S35="","Проверить: отметьте дубль",IF(S35="Нужно проверить","Проверить возможный дубль",IF(TODAY()-E35>30,"Проверить: старше 30 дней",IF(COUNTIFS(#REF!,G35,#REF!,"Готово")=0,"Проверить источник","Готово"))))))))))
A36: Python parser | B36: 2026-09-23 | C36: Республика Коми | E36: 2026-09-03 | G36: Государственный Совет Республики Коми | H36: https://www.gsrk.ru/presscenter/news/85388/ | J36: I заседание III сессии Государственного Совета Республики Коми VIII созыва состоится 24 сентября 2026 года | K36: Власть и кадровые решения | L36: Анонс | M36: Председатель Государственного Совета Республики Коми А.П. Макаренко подписал распоряжение о проведении I заседания III сессии Государственного Совета Республики Коми VIII созыва 24 сентября 2026 года в городе Сыктывкаре с 10 часов в большом зале Государственного Совета Республики Коми по адресу: г. Сыктывкар ул. Коммунистическая, 8. | U36: =IF(COUNTA(A36:T36)=0,"",IF(OR(A36="",B36="",C36="",E36="",G36="",H36="",J36="",K36="",L36="",M36=""),"Ошибка: заполните обязательные поля",IF(AND(LEFT(H36,7)<>"http://",LEFT(H36,8)<>"https://"),"Ошибка: некорректная ссылка",IF(COUNTIF($H$6:$H$1005,H36)>1,"Ошибка: дубликат URL",IF(E36>TODAY(),"Ошибка: дата публикации в будущем",IF(S36="Да","Ошибка: подтверждённый дубль",IF(S36="","Проверить: отметьте дубль",IF(S36="Нужно проверить","Проверить возможный дубль",IF(TODAY()-E36>30,"Проверить: старше 30 дней",IF(COUNTIFS(#REF!,G36,#REF!,"Готово")=0,"Проверить источник","Готово"))))))))))
A37: Python parser | B37: 2026-09-23 | C37: Республика Коми | E37: 2026-09-09 | G37: Министерство закупок Республики Коми | H37: https://zakupki.rkomi.ru/presscenter/news/85600/ | J37: Суд: реестровая запись без сведений о баллах не подтверждает российское происхождение товара, если баллы установлены для вышестоящего кода ОКПД2 | K37: Закупки и контракты | M37: Суд рассмотрел дело о подтверждении российского происхождения спасательных гидрокостюмов при проведении электронного аукциона, указав, что реестровые записи без баллов не подтверждают происхождение товара. | N37: Начальная цена закупки около 1,5 млн рублей; ограничение по Постановлению № 1875; отсутствие реестровой записи у одного участника, некорректность информации у другого участника. | R37: Республика Коми | U37: =IF(COUNTA(A37:T37)=0,"",IF(OR(A37="",B37="",C37="",E37="",G37="",H37="",J37="",K37="",L37="",M37=""),"Ошибка: заполните обязательные поля",IF(AND(LEFT(H37,7)<>"http://",LEFT(H37,8)<>"https://"),"Ошибка: некорректная ссылка",IF(COUNTIF($H$6:$H$1005,H37)>1,"Ошибка: дубликат URL",IF(E37>TODAY(),"Ошибка: дата публикации в будущем",IF(S37="Да","Ошибка: подтверждённый дубль",IF(S37="","Проверить: отметьте дубль",IF(S37="Нужно проверить","Проверить возможный дубль",IF(TODAY()-E37>30,"Проверить: старше 30 дней",IF(COUNTIFS(#REF!,G37,#REF!,"Готово")=0,"Проверить источник","Готово"))))))))))
A38: Python parser | B38: 2026-09-23 | C38: Республика Коми | E38: 2026-09-07 | G38: Министерство закупок Республики Коми | H38: https://zakupki.rkomi.ru/presscenter/news/85470/ | J38: ЖКХ, дороги, здравоохранение: на Прямую линию с Главой Республики Коми Ростиславом Гольдштейном поступают вопросы жителей по самым актуальным темам. | K38: Обращения и проблемы жителей | L38: Анонс | M38: На сегодняшний день поступило порядка 1000 обращений. Большинство из них касается качества предоставления жилищно-коммунальных услуг, состояния дорог и доступности медицинской помощи. Напомним, 10 сентября Глава Республики Коми Ростислав Гольдштейн проведёт Прямую линию, совмещённую с пресс-конференцией. Задать свой вопрос руководителю региона можно: | U38: =IF(COUNTA(A38:T38)=0,"",IF(OR(A38="",B38="",C38="",E38="",G38="",H38="",J38="",K38="",L38="",M38=""),"Ошибка: заполните обязательные поля",IF(AND(LEFT(H38,7)<>"http://",LEFT(H38,8)<>"https://"),"Ошибка: некорректная ссылка",IF(COUNTIF($H$6:$H$1005,H38)>1,"Ошибка: дубликат URL",IF(E38>TODAY(),"Ошибка: дата публикации в будущем",IF(S38="Да","Ошибка: подтверждённый дубль",IF(S38="","Проверить: отметьте дубль",IF(S38="Нужно проверить","Проверить возможный дубль",IF(TODAY()-E38>30,"Проверить: старше 30 дней",IF(COUNTIFS(#REF!,G38,#REF!,"Готово")=0,"Проверить источник","Готово"))))))))))
A39: Python parser | B39: 2026-09-23 | C39: Республика Коми | E39: 2026-09-01 | G39: Министерство закупок Республики Коми | H39: https://zakupki.rkomi.ru/presscenter/news/85255/ | J39: Уважаемые заказчики Республики Коми! | K39: Закупки и контракты | M39: Министерство закупок Республики Коми обновило требования к представлению информации и документов, подтверждающих страну происхождения товаров для участия в закупках. | N39: Актуализированы формулировки требований; ссылка на официальный сайт министерства с примерами указаний; постановление Правительства РФ № 1875; Федеральный закон № 44-ФЗ. | P39: Министерство закупок Республики Коми | U39: =IF(COUNTA(A39:T39)=0,"",IF(OR(A39="",B39="",C39="",E39="",G39="",H39="",J39="",K39="",L39="",M39=""),"Ошибка: заполните обязательные поля",IF(AND(LEFT(H39,7)<>"http://",LEFT(H39,8)<>"https://"),"Ошибка: некорректная ссылка",IF(COUNTIF($H$6:$H$1005,H39)>1,"Ошибка: дубликат URL",IF(E39>TODAY(),"Ошибка: дата публикации в будущем",IF(S39="Да","Ошибка: подтверждённый дубль",IF(S39="","Проверить: отметьте дубль",IF(S39="Нужно проверить","Проверить возможный дубль",IF(TODAY()-E39>30,"Проверить: старше 30 дней",IF(COUNTIFS(#REF!,G39,#REF!,"Готово")=0,"Проверить источник","Готово"))))))))))
A40: Python parser | B40: 2026-09-23 | C40: Республика Коми | E40: 2026-09-02 | G40: Министерство здравоохранения Республики Коми | H40: https://minzdrav.rkomi.ru/presscenter/news/85290/ | J40: Будущее здравоохранения: министр поздравила студентов‑медиков Коми с началом учебного года | K40: Образование | L40: Анонс | M40: Министр здравоохранения Республики Коми Ирина Кондратьева поздравила студентов медицинских вузов и колледжей с началом учебного года и подчеркнула важность подготовки будущих специалистов для системы здравоохранения региона. | N40: В 2026 году систему здравоохранения республики пополнили 498 выпускников; 496 новых студентов начали обучение в медицинском колледже; в медицинский институт принято 116 человек на направления 'Лечебное дело' и 'Педиатрия'; в ординатуру зачислены 53 студента. | O40: Ирина Кондратьева - министр здравоохранения Республики Коми | P40: Сыктывкарский государственный университет, Сыктывкарский медицинский колледж, медицинский институт | R40: Республика Коми | U40: =IF(COUNTA(A40:T40)=0,"",IF(OR(A40="",B40="",C40="",E40="",G40="",H40="",J40="",K40="",L40="",M40=""),"Ошибка: заполните обязательные поля",IF(AND(LEFT(H40,7)<>"http://",LEFT(H40,8)<>"https://"),"Ошибка: некорректная ссылка",IF(COUNTIF($H$6:$H$1005,H40)>1,"Ошибка: дубликат URL",IF(E40>TODAY(),"Ошибка: дата публикации в будущем",IF(S40="Да","Ошибка: подтверждённый дубль",IF(S40="","Проверить: отметьте дубль",IF(S40="Нужно проверить","Проверить возможный дубль",IF(TODAY()-E40>30,"Проверить: старше 30 дней",IF(COUNTIFS(#REF!,G40,#REF!,"Готово")=0,"Проверить источник","Готово"))))))))))
A41: Python parser | B41: 2026-09-23 | C41: Республика Коми | E41: 2026-09-09 | G41: Министерство здравоохранения Республики Коми | H41: https://minzdrav.rkomi.ru/presscenter/news/85601/ | J41: 12 сентября — ваш шанс быстро и удобно проверить здоровье в Орбите! | K41: Здоровье | M41: 12 сентября в Орбите пройдет акция по проверке здоровья с различными медицинскими процедурами и тестами. | N41: Проведение акции с 10:00 до 15:00; виды медицинских процедур: измерение давления, проверка веса и роста, внутриглазного давления, уровня кислорода в крови, функции внешнего дыхания, экспресс-тесты на сахар и холестерин. | R41: Орбита | U41: =IF(COUNTA(A41:T41)=0,"",IF(OR(A41="",B41="",C41="",E41="",G41="",H41="",J41="",K41="",L41="",M41=""),"Ошибка: заполните обязательные поля",IF(AND(LEFT(H41,7)<>"http://",LEFT(H41,8)<>"https://"),"Ошибка: некорректная ссылка",IF(COUNTIF($H$6:$H$1005,H41)>1,"Ошибка: дубликат URL",IF(E41>TODAY(),"Ошибка: дата публикации в будущем",IF(S41="Да","Ошибка: подтверждённый дубль",IF(S41="","Проверить: отметьте дубль",IF(S41="Нужно проверить","Проверить возможный дубль",IF(TODAY()-E41>30,"Проверить: старше 30 дней",IF(COUNTIFS(#REF!,G41,#REF!,"Готово")=0,"Проверить источник","Готово"))))))))))
A42: Python parser | B42: 2026-09-23 | C42: Республика Коми | E42: 2026-09-04 | G42: Министерство здравоохранения Республики Коми | H42: https://minzdrav.rkomi.ru/presscenter/news/85458/ | J42: Электронное голосование | K42: Власть и кадровые решения | L42: Анонс | M42: На выборах в Коми применяют несколько форм голосования, среди которых есть дистанционное электронное голосование (ДЭГ) . До 14 сентября принимают заявления о включении в список избирателей для участия в ДЭГ и для голосования по месту нахождения. | U42: =IF(COUNTA(A42:T42)=0,"",IF(OR(A42="",B42="",C42="",E42="",G42="",H42="",J42="",K42="",L42="",M42=""),"Ошибка: заполните обязательные поля",IF(AND(LEFT(H42,7)<>"http://",LEFT(H42,8)<>"https://"),"Ошибка: некорректная ссылка",IF(COUNTIF($H$6:$H$1005,H42)>1,"Ошибка: дубликат URL",IF(E42>TODAY(),"Ошибка: дата публикации в будущем",IF(S42="Да","Ошибка: подтверждённый дубль",IF(S42="","Проверить: отметьте дубль",IF(S42="Нужно проверить","Проверить возможный дубль",IF(TODAY()-E42>30,"Проверить: старше 30 дней",IF(COUNTIFS(#REF!,G42,#REF!,"Готово")=0,"Проверить источник","Готово"))))))))))
A43: Python parser | B43: 2026-09-23 | C43: Республика Коми | E43: 2026-09-04 | G43: Министерство здравоохранения Республики Коми | H43: https://minzdrav.rkomi.ru/presscenter/news/85451/ | J43: 10 сентября Глава Республики Коми Ростислав Гольдштейн проведёт Прямую линию, совмещённую с пресс-конференцией | K43: Власть и кадровые решения | L43: Решение принято | M43: ЖКХ, дороги, здравоохранение: на Прямую линию с Главой Республики Коми Ростиславом Гольдштейном поступают вопросы жителей по самым актуальным темам. На сегодняшний день поступило порядка 1000 обращений. Большинство из них касается качества предоставления жилищно-коммунальных услуг, состояния дорог и доступности медицинской помощи. Напомним, 10 сентября Глава Республики Коми Ростислав Гольдштейн проведёт Прямую линию, совмещённую с пресс-конференцией. | U43: =IF(COUNTA(A43:T43)=0,"",IF(OR(A43="",B43="",C43="",E43="",G43="",H43="",J43="",K43="",L43="",M43=""),"Ошибка: заполните обязательные поля",IF(AND(LEFT(H43,7)<>"http://",LEFT(H43,8)<>"https://"),"Ошибка: некорректная ссылка",IF(COUNTIF($H$6:$H$1005,H43)>1,"Ошибка: дубликат URL",IF(E43>TODAY(),"Ошибка: дата публикации в будущем",IF(S43="Да","Ошибка: подтверждённый дубль",IF(S43="","Проверить: отметьте дубль",IF(S43="Нужно проверить","Проверить возможный дубль",IF(TODAY()-E43>30,"Проверить: старше 30 дней",IF(COUNTIFS(#REF!,G43,#REF!,"Готово")=0,"Проверить источник","Готово"))))))))))
A44: Python parser | B44: 2026-09-23 | C44: Республика Коми | E44: 2026-09-01 | G44: Министерство здравоохранения Республики Коми | H44: https://minzdrav.rkomi.ru/presscenter/news/84269/ | J44: Как подготовиться к рождению ребенка расскажет портал «Госуслуги» | K44: Социальная сфера | M44: На портале 'Госуслуги' размещена информация о подготовке к беременности и родам, включая необходимые документы и рекомендации. | N44: Жизненная ситуация 'Планирование и рождение ребенка' включает этапы планирования беременности, ведения беременности и рождения ребенка; требуется подготовка перед отправкой в роддом; после рождения ребенка можно оформить свидетельство о рождении онлайн; СНИЛС и полис ОМС новорожденному присваиваются автоматически. | R44: Республика Коми | U44: =IF(COUNTA(A44:T44)=0,"",IF(OR(A44="",B44="",C44="",E44="",G44="",H44="",J44="",K44="",L44="",M44=""),"Ошибка: заполните обязательные поля",IF(AND(LEFT(H44,7)<>"http://",LEFT(H44,8)<>"https://"),"Ошибка: некорректная ссылка",IF(COUNTIF($H$6:$H$1005,H44)>1,"Ошибка: дубликат URL",IF(E44>TODAY(),"Ошибка: дата публикации в будущем",IF(S44="Да","Ошибка: подтверждённый дубль",IF(S44="","Проверить: отметьте дубль",IF(S44="Нужно проверить","Проверить возможный дубль",IF(TODAY()-E44>30,"Проверить: старше 30 дней",IF(COUNTIFS(#REF!,G44,#REF!,"Готово")=0,"Проверить источник","Готово"))))))))))
A45: Python parser | B45: 2026-09-23 | C45: Республика Коми | E45: 2026-08-31 | G45: Министерство здравоохранения Республики Коми | H45: https://minzdrav.rkomi.ru/presscenter/news/84733/ | J45: «Прогулки меняют»: в Воркуте с паллиативными пациентами больницы гуляют добровольцы | K45: Социальная сфера | M45: Воркутинская больница скорой помощи запустила проект 'Прогулки доброты', при котором добровольцы гуляют с паллиативными пациентами на свежем воздухе, улучшая их настроение. | O45: Галина Курдюкова (главная медицинская сестра воркутинской больницы) | P45: Воркутинская больница скорой помощи | R45: Воркута | U45: =IF(COUNTA(A45:T45)=0,"",IF(OR(A45="",B45="",C45="",E45="",G45="",H45="",J45="",K45="",L45="",M45=""),"Ошибка: заполните обязательные поля",IF(AND(LEFT(H45,7)<>"http://",LEFT(H45,8)<>"https://"),"Ошибка: некорректная ссылка",IF(COUNTIF($H$6:$H$1005,H45)>1,"Ошибка: дубликат URL",IF(E45>TODAY(),"Ошибка: дата публикации в будущем",IF(S45="Да","Ошибка: подтверждённый дубль",IF(S45="","Проверить: отметьте дубль",IF(S45="Нужно проверить","Проверить возможный дубль",IF(TODAY()-E45>30,"Проверить: старше 30 дней",IF(COUNTIFS(#REF!,G45,#REF!,"Готово")=0,"Проверить источник","Готово"))))))))))
A46: Python parser | B46: 2026-09-23 | C46: Республика Коми | E46: 2026-08-28 | G46: Министерство здравоохранения Республики Коми | H46: https://minzdrav.rkomi.ru/presscenter/news/85179/ | J46: Заботьтесь о здоровье по субботам! | K46: Здравоохранение | L46: Решение принято | M46: С 29 августа в пгт Краснозатонский будет работать мобильный флюорограф для обследования легких жителей. | N46: Время работы: с 10:00 до 14:00; Место проведения: площадь им. Е.В. Чепыгина; Целевая аудитория: жители пгт Краснозатонский. | R46: пгт Краснозатонский | U46: =IF(COUNTA(A46:T46)=0,"",IF(OR(A46="",B46="",C46="",E46="",G46="",H46="",J46="",K46="",L46="",M46=""),"Ошибка: заполните обязательные поля",IF(AND(LEFT(H46,7)<>"http://",LEFT(H46,8)<>"https://"),"Ошибка: некорректная ссылка",IF(COUNTIF($H$6:$H$1005,H46)>1,"Ошибка: дубликат URL",IF(E46>TODAY(),"Ошибка: дата публикации в будущем",IF(S46="Да","Ошибка: подтверждённый дубль",IF(S46="","Проверить: отметьте дубль",IF(S46="Нужно проверить","Проверить возможный дубль",IF(TODAY()-E46>30,"Проверить: старше 30 дней",IF(COUNTIFS(#REF!,G46,#REF!,"Готово")=0,"Проверить источник","Готово"))))))))))
A47: Python parser | B47: 2026-09-23 | C47: Республика Коми | E47: 2026-09-07 | G47: Министерство имущественных и земельных отношений Республики Коми | H47: https://agui.rkomi.ru/presscenter/news/85467/ | J47: ЖКХ, дороги, здравоохранение: на Прямую линию с Главой Республики Коми Ростиславом Гольдштейном поступают вопросы жителей по самым актуальным темам | K47: Обращения и проблемы жителей | L47: Проблема / происшествие | M47: ЖКХ, дороги, здравоохранение: на Прямую линию с Главой Республики Коми Ростиславом Гольдштейном поступают вопросы жителей по самым актуальным темам | U47: =IF(COUNTA(A47:T47)=0,"",IF(OR(A47="",B47="",C47="",E47="",G47="",H47="",J47="",K47="",L47="",M47=""),"Ошибка: заполните обязательные поля",IF(AND(LEFT(H47,7)<>"http://",LEFT(H47,8)<>"https://"),"Ошибка: некорректная ссылка",IF(COUNTIF($H$6:$H$1005,H47)>1,"Ошибка: дубликат URL",IF(E47>TODAY(),"Ошибка: дата публикации в будущем",IF(S47="Да","Ошибка: подтверждённый дубль",IF(S47="","Проверить: отметьте дубль",IF(S47="Нужно проверить","Проверить возможный дубль",IF(TODAY()-E47>30,"Проверить: старше 30 дней",IF(COUNTIFS(#REF!,G47,#REF!,"Готово")=0,"Проверить источник","Готово"))))))))))
A48: Python parser | B48: 2026-09-23 | C48: Республика Коми | E48: 2026-09-03 | G48: Министерство имущественных и земельных отношений Республики Коми | H48: https://agui.rkomi.ru/presscenter/news/85407/ | J48: «Команда Республики Коми» взяла на контроль транспортную доступность в селе Озёл и пст Трехозерка | K48: Происшествия и безопасность | L48: Проблема / происшествие | M48: Министры и глава муниципалитета провели встречу с жителями села Озёл и посёлка Трехозерка для обсуждения транспортных и медицинских проблем, регистрации безработных, отсутствия сотовой связи и получения пенсионных выплат. | N48: Проведена встреча с жителями; обсуждались транспортные и медицинские проблемы, регистрация безработных, отсутствие сотовой связи, получение пенсионных выплат; министры и глава муниципалитета прошли по окрестностям села и осмотрели имущественные объекты. | O48: Людмила Забоева (Министр имущественных и земельных отношений РК), Ирина Кондратьева (Министр здравоохранения РК), Илья Семяшкин (Глава МР «Сыктывдинский»), Наталья Сурадейкина (глава поселения) | P48: Республика Коми, Министерство имущественных и земельных отношений РК, Министерство здравоохранения РК, МР «Сыктывдинский» | R48: село Озёл, посёлок Трехозерка | U48: =IF(COUNTA(A48:T48)=0,"",IF(OR(A48="",B48="",C48="",E48="",G48="",H48="",J48="",K48="",L48="",M48=""),"Ошибка: заполните обязательные поля",IF(AND(LEFT(H48,7)<>"http://",LEFT(H48,8)<>"https://"),"Ошибка: некорректная ссылка",IF(COUNTIF($H$6:$H$1005,H48)>1,"Ошибка: дубликат URL",IF(E48>TODAY(),"Ошибка: дата публикации в будущем",IF(S48="Да","Ошибка: подтверждённый дубль",IF(S48="","Проверить: отметьте дубль",IF(S48="Нужно проверить","Проверить возможный дубль",IF(TODAY()-E48>30,"Проверить: старше 30 дней",IF(COUNTIFS(#REF!,G48,#REF!,"Готово")=0,"Проверить источник","Готово"))))))))))
A49: Python parser | B49: 2026-09-23 | C49: Республика Коми | E49: 2026-09-02 | G49: Министерство имущественных и земельных отношений Республики Коми | H49: https://agui.rkomi.ru/presscenter/news/85286/ | J49: Республика Коми получила дивиденды от государственных компаний за 2025 год | K49: Муниципальные финансы | M49: В 2026 году в бюджет Республики Коми поступили дивиденды от 10 государственных компаний на сумму 553,01 млн рублей, впервые от акционерного общества «Коми дорожная компания». Средства направляются на социальные программы и стратегические проекты. | N49: Сумма поступивших дивидендов: 553,01 млн рублей; впервые дивиденды получены от АО «Коми дорожная компания»; средства будут направлены на социальные программы и развитие региона. | R49: Республика Коми | U49: =IF(COUNTA(A49:T49)=0,"",IF(OR(A49="",B49="",C49="",E49="",G49="",H49="",J49="",K49="",L49="",M49=""),"Ошибка: заполните обязательные поля",IF(AND(LEFT(H49,7)<>"http://",LEFT(H49,8)<>"https://"),"Ошибка: некорректная ссылка",IF(COUNTIF($H$6:$H$1005,H49)>1,"Ошибка: дубликат URL",IF(E49>TODAY(),"Ошибка: дата публикации в будущем",IF(S49="Да","Ошибка: подтверждённый дубль",IF(S49="","Проверить: отметьте дубль",IF(S49="Нужно проверить","Проверить возможный дубль",IF(TODAY()-E49>30,"Проверить: старше 30 дней",IF(COUNTIFS(#REF!,G49,#REF!,"Готово")=0,"Проверить источник","Готово"))))))))))
A50: Python parser | B50: 2026-09-23 | C50: Республика Коми | E50: 2026-09-02 | G50: Министерство имущественных и земельных отношений Республики Коми | H50: https://agui.rkomi.ru/presscenter/news/85285/ | J50: Как задать вопрос Главе Коми? Ростислав Гольдштейн проведет прямую линию 10 сентября. | K50: Другое | L50: Анонс | M50: Как задать вопрос Главе Коми? Ростислав Гольдштейн проведет прямую линию 10 сентября. | U50: =IF(COUNTA(A50:T50)=0,"",IF(OR(A50="",B50="",C50="",E50="",G50="",H50="",J50="",K50="",L50="",M50=""),"Ошибка: заполните обязательные поля",IF(AND(LEFT(H50,7)<>"http://",LEFT(H50,8)<>"https://"),"Ошибка: некорректная ссылка",IF(COUNTIF($H$6:$H$1005,H50)>1,"Ошибка: дубликат URL",IF(E50>TODAY(),"Ошибка: дата публикации в будущем",IF(S50="Да","Ошибка: подтверждённый дубль",IF(S50="","Проверить: отметьте дубль",IF(S50="Нужно проверить","Проверить возможный дубль",IF(TODAY()-E50>30,"Проверить: старше 30 дней",IF(COUNTIFS(#REF!,G50,#REF!,"Готово")=0,"Проверить источник","Готово"))))))))))
...

Sheet Справочники
A1: Служебные справочники — не редактировать
A3: Муниципалитеты | B3: Категории | C3: Платформы | D3: Стадии | E3: Типы источников | F3: Официальность | G3: Активность | H3: Дубли
A4: Воркута | B4: Власть и кадровые решения | C4: Официальный сайт | D4: Анонс | E4: Администрация муниципалитета | F4: Подтверждено | G4: Активен | H4: Нет
A5: Вуктыл | B5: Бюджет и муниципальные финансы | C5: MAX | D5: Решение принято | E5: Глава муниципалитета | F5: Не подтверждено | G5: Неактивен | H5: Да
A6: Ижемский район | B6: Закупки и контракты | C6: ВКонтакте | D6: Финансирование выделено | E6: Совет / представительный орган | F6: Требует проверки | G6: Недоступен | H6: Нужно проверить
A7: Инта | B7: Строительство и инфраструктура | C7: Telegram | D7: Закупка объявлена | E7: Муниципальное учреждение | G7: Требует проверки
A8: Княжпогостский район | B8: ЖКХ и благоустройство | C8: Одноклассники | D8: Работы начаты | E8: Региональный орган власти
A9: Койгородский район | B9: Экономика, бизнес и занятость | C9: Rutube | D9: В процессе | E9: Официальная пресс-служба
A10: Корткеросский район | B10: Социальная сфера | C10: Другое | D10: Завершено / открыто | E10: Другое официальное
A11: Печора | B11: Образование | D11: Перенесено / приостановлено | E11: Неофициальный источник
A12: Прилузский район | B12: Здравоохранение | D12: Проблема / происшествие
A13: Сосногорск | B13: Происшествия и безопасность | D13: Результат
A14: Сыктывдинский район | B14: Экология
A15: Сыктывкар | B15: Обращения и проблемы жителей
A16: Сысольский район | B16: Культура, спорт и туризм
A17: Троицко-Печорский район | B17: Банки и финансовые сервисы
A18: Удорский район | B18: Другое
A19: Усинск
A20: Усть-Вымский район
A21: Усть-Куломский район
A22: Усть-Цилемский район
A23: Ухта
A24: Республика Коми

Sheet Контроль
A1: Контроль покрытия муниципалитетов — служебный лист
A2: Показатели рассчитываются автоматически по основному муниципалитету.
A3: Муниципалитет | B3: Всего источников | C3: Готовых источников | D3: Новостей за 30 дней | E3: Готовых новостей | F3: Нужно проверить | G3: Ошибки
A4: Воркута | B4: =COUNTIF(#REF!,A4) | C4: =COUNTIFS(#REF!,A4,#REF!,"Готово") | D4: =COUNTIFS(Новости!$C$6:$C$1005,A4,Новости!$E$6:$E$1005,">="&TODAY()-30) | E4: =COUNTIFS(Новости!$C$6:$C$1005,A4,Новости!$U$6:$U$1005,"Готово") | F4: =COUNTIFS(Новости!$C$6:$C$1005,A4,Новости!$U$6:$U$1005,"Проверить*") | G4: =COUNTIFS(Новости!$C$6:$C$1005,A4,Новости!$U$6:$U$1005,"Ошибка*")
A5: Вуктыл | B5: =COUNTIF(#REF!,A5) | C5: =COUNTIFS(#REF!,A5,#REF!,"Готово") | D5: =COUNTIFS(Новости!$C$6:$C$1005,A5,Новости!$E$6:$E$1005,">="&TODAY()-30) | E5: =COUNTIFS(Новости!$C$6:$C$1005,A5,Новости!$U$6:$U$1005,"Готово") | F5: =COUNTIFS(Новости!$C$6:$C$1005,A5,Новости!$U$6:$U$1005,"Проверить*") | G5: =COUNTIFS(Новости!$C$6:$C$1005,A5,Новости!$U$6:$U$1005,"Ошибка*")
A6: Ижемский район | B6: =COUNTIF(#REF!,A6) | C6: =COUNTIFS(#REF!,A6,#REF!,"Готово") | D6: =COUNTIFS(Новости!$C$6:$C$1005,A6,Новости!$E$6:$E$1005,">="&TODAY()-30) | E6: =COUNTIFS(Новости!$C$6:$C$1005,A6,Новости!$U$6:$U$1005,"Готово") | F6: =COUNTIFS(Новости!$C$6:$C$1005,A6,Новости!$U$6:$U$1005,"Проверить*") | G6: =COUNTIFS(Новости!$C$6:$C$1005,A6,Новости!$U$6:$U$1005,"Ошибка*")
A7: Инта | B7: =COUNTIF(#REF!,A7) | C7: =COUNTIFS(#REF!,A7,#REF!,"Готово") | D7: =COUNTIFS(Новости!$C$6:$C$1005,A7,Новости!$E$6:$E$1005,">="&TODAY()-30) | E7: =COUNTIFS(Новости!$C$6:$C$1005,A7,Новости!$U$6:$U$1005,"Готово") | F7: =COUNTIFS(Новости!$C$6:$C$1005,A7,Новости!$U$6:$U$1005,"Проверить*") | G7: =COUNTIFS(Новости!$C$6:$C$1005,A7,Новости!$U$6:$U$1005,"Ошибка*")
A8: Княжпогостский район | B8: =COUNTIF(#REF!,A8) | C8: =COUNTIFS(#REF!,A8,#REF!,"Готово") | D8: =COUNTIFS(Новости!$C$6:$C$1005,A8,Новости!$E$6:$E$1005,">="&TODAY()-30) | E8: =COUNTIFS(Новости!$C$6:$C$1005,A8,Новости!$U$6:$U$1005,"Готово") | F8: =COUNTIFS(Новости!$C$6:$C$1005,A8,Новости!$U$6:$U$1005,"Проверить*") | G8: =COUNTIFS(Новости!$C$6:$C$1005,A8,Новости!$U$6:$U$1005,"Ошибка*")
A9: Койгородский район | B9: =COUNTIF(#REF!,A9) | C9: =COUNTIFS(#REF!,A9,#REF!,"Готово") | D9: =COUNTIFS(Новости!$C$6:$C$1005,A9,Новости!$E$6:$E$1005,">="&TODAY()-30) | E9: =COUNTIFS(Новости!$C$6:$C$1005,A9,Новости!$U$6:$U$1005,"Готово") | F9: =COUNTIFS(Новости!$C$6:$C$1005,A9,Новости!$U$6:$U$1005,"Проверить*") | G9: =COUNTIFS(Новости!$C$6:$C$1005,A9,Новости!$U$6:$U$1005,"Ошибка*")
A10: Корткеросский район | B10: =COUNTIF(#REF!,A10) | C10: =COUNTIFS(#REF!,A10,#REF!,"Готово") | D10: =COUNTIFS(Новости!$C$6:$C$1005,A10,Новости!$E$6:$E$1005,">="&TODAY()-30) | E10: =COUNTIFS(Новости!$C$6:$C$1005,A10,Новости!$U$6:$U$1005,"Готово") | F10: =COUNTIFS(Новости!$C$6:$C$1005,A10,Новости!$U$6:$U$1005,"Проверить*") | G10: =COUNTIFS(Новости!$C$6:$C$1005,A10,Новости!$U$6:$U$1005,"Ошибка*")
A11: Печора | B11: =COUNTIF(#REF!,A11) | C11: =COUNTIFS(#REF!,A11,#REF!,"Готово") | D11: =COUNTIFS(Новости!$C$6:$C$1005,A11,Новости!$E$6:$E$1005,">="&TODAY()-30) | E11: =COUNTIFS(Новости!$C$6:$C$1005,A11,Новости!$U$6:$U$1005,"Готово") | F11: =COUNTIFS(Новости!$C$6:$C$1005,A11,Новости!$U$6:$U$1005,"Проверить*") | G11: =COUNTIFS(Новости!$C$6:$C$1005,A11,Новости!$U$6:$U$1005,"Ошибка*")
A12: Прилузский район | B12: =COUNTIF(#REF!,A12) | C12: =COUNTIFS(#REF!,A12,#REF!,"Готово") | D12: =COUNTIFS(Новости!$C$6:$C$1005,A12,Новости!$E$6:$E$1005,">="&TODAY()-30) | E12: =COUNTIFS(Новости!$C$6:$C$1005,A12,Новости!$U$6:$U$1005,"Готово") | F12: =COUNTIFS(Новости!$C$6:$C$1005,A12,Новости!$U$6:$U$1005,"Проверить*") | G12: =COUNTIFS(Новости!$C$6:$C$1005,A12,Новости!$U$6:$U$1005,"Ошибка*")
A13: Сосногорск | B13: =COUNTIF(#REF!,A13) | C13: =COUNTIFS(#REF!,A13,#REF!,"Готово") | D13: =COUNTIFS(Новости!$C$6:$C$1005,A13,Новости!$E$6:$E$1005,">="&TODAY()-30) | E13: =COUNTIFS(Новости!$C$6:$C$1005,A13,Новости!$U$6:$U$1005,"Готово") | F13: =COUNTIFS(Новости!$C$6:$C$1005,A13,Новости!$U$6:$U$1005,"Проверить*") | G13: =COUNTIFS(Новости!$C$6:$C$1005,A13,Новости!$U$6:$U$1005,"Ошибка*")
A14: Сыктывдинский район | B14: =COUNTIF(#REF!,A14) | C14: =COUNTIFS(#REF!,A14,#REF!,"Готово") | D14: =COUNTIFS(Новости!$C$6:$C$1005,A14,Новости!$E$6:$E$1005,">="&TODAY()-30) | E14: =COUNTIFS(Новости!$C$6:$C$1005,A14,Новости!$U$6:$U$1005,"Готово") | F14: =COUNTIFS(Новости!$C$6:$C$1005,A14,Новости!$U$6:$U$1005,"Проверить*") | G14: =COUNTIFS(Новости!$C$6:$C$1005,A14,Новости!$U$6:$U$1005,"Ошибка*")
A15: Сыктывкар | B15: =COUNTIF(#REF!,A15) | C15: =COUNTIFS(#REF!,A15,#REF!,"Готово") | D15: =COUNTIFS(Новости!$C$6:$C$1005,A15,Новости!$E$6:$E$1005,">="&TODAY()-30) | E15: =COUNTIFS(Новости!$C$6:$C$1005,A15,Новости!$U$6:$U$1005,"Готово") | F15: =COUNTIFS(Новости!$C$6:$C$1005,A15,Новости!$U$6:$U$1005,"Проверить*") | G15: =COUNTIFS(Новости!$C$6:$C$1005,A15,Новости!$U$6:$U$1005,"Ошибка*")
... A23: Ухта | B23: =COUNTIF(#REF!,A23) | C23: =COUNTIFS(#REF!,A23,#REF!,"Готово") | D23: =COUNTIFS(Новости!$C$6:$C$1005,A23,Новости!$E$6:$E$1005,">="&TODAY()-30) | E23: =COUNTIFS(Новости!$C$6:$C$1005,A23,Новости!$U$6:$U$1005,"Готово") | F23: =COUNTIFS(Новости!$C$6:$C$1005,A23,Новости!$U$6:$U$1005,"Проверить*") | G23: =COUNTIFS(Новости!$C$6:$C$1005,A23,Новости!$U$6:$U$1005,"Ошибка*")
A25: Итого | B25: =SUM(B4:B23) | C25: =SUM(C4:C23) | D25: =SUM(D4:D23) | E25: =SUM(E4:E23) | F25: =SUM(F4:F23) | G25: =SUM(G4:G23)
