Workbook

Sheet Источники
A1: Реестр официальных источников по муниципалитетам Республики Коми
A2: Сначала найдите источник и подтвердите его официальность. Приоритет — сайты и публичные каналы муниципалитетов. Старые строки не удалять. Столбец «Автопроверка» не редактировать.
A3: Обязательное
A5: Сборщик | B5: Дата проверки | C5: Муниципалитет | D5: Орган/владелец | E5: Тип источника | F5: Платформа | G5: Название | H5: Основная ссылка | I5: Подтверждение официальности | J5: Дата последней публикации | K5: Активность | L5: Комментарий | M5: Автопроверка
A6: Максим | B6: 46267 | C6: Республика Коми | D6: Банка об этом не напишет | E6: Неофициальный источник | F6: Telegram | G6: Банка об этом не напишет | H6: https://t.me/notBNK | I6: Не подтверждено | K6: Активен | L6: Проверено 02.09.2026: доступен. | M6: =IFERROR(__xludf.DUMMYFUNCTION("IF(COUNTA(A6:L6)=0,"""",IFS(AND(H6<>"""",COUNTIF($H$6:$H$504,H6)>1),""Ошибка: повтор URL"",OR(A6="""",B6="""",C6="""",D6="""",E6="""",F6="""",G6="""",H6="""",K6=""""),""Ошибка: обязательные поля"",NOT(REGEXMATCH(H6,""^https?://[^ /]+"")),""Ошибка: некорре"&"ктная ссылка"",COUNTIF('Справочники'!$A$4:$A$24,C6)=0,""Ошибка: территория вне справочника"",K6=""Недоступен"",""Ошибка: ссылка недоступна"",E6=""Неофициальный источник"",IF(K6=""Активен"",""Готово"",""Проверить: активность""),I6<>""Подтверждено"",""Прове"&"рить: официальность / комментарий"",K6<>""Активен"",""Проверить: активность"",AND(ISNUMBER(J6),J6<TODAY()-30),""Проверить: публикации старше 30 дней"",TRUE,""Готово""))"),"Готово") -> Готово
A7: Максим | B7: 46267 | C7: Республика Коми | D7: БНК | E7: Неофициальный источник | F7: Telegram | G7: БНК | H7: https://t.me/bnk11 | I7: Подтверждено | K7: Активен | L7: Повтор URL: строки 14, 303. Проверено 02.09.2026: доступен. | M7: =IFERROR(__xludf.DUMMYFUNCTION("IF(COUNTA(A7:L7)=0,"""",IFS(AND(H7<>"""",COUNTIF($H$6:$H$504,H7)>1),""Ошибка: повтор URL"",OR(A7="""",B7="""",C7="""",D7="""",E7="""",F7="""",G7="""",H7="""",K7=""""),""Ошибка: обязательные поля"",NOT(REGEXMATCH(H7,""^https?://[^ /]+"")),""Ошибка: некорре"&"ктная ссылка"",COUNTIF('Справочники'!$A$4:$A$24,C7)=0,""Ошибка: территория вне справочника"",K7=""Недоступен"",""Ошибка: ссылка недоступна"",E7=""Неофициальный источник"",IF(K7=""Активен"",""Готово"",""Проверить: активность""),I7<>""Подтверждено"",""Прове"&"рить: официальность / комментарий"",K7<>""Активен"",""Проверить: активность"",AND(ISNUMBER(J7),J7<TODAY()-30),""Проверить: публикации старше 30 дней"",TRUE,""Готово""))"),"Готово") -> Готово
A8: Максим | B8: 46267 | C8: Воркута | D8: Администрация Воркуты | E8: Администрация муниципалитета | F8: Telegram | G8: Воркута.Официально | H8: https://t.me/officially_vorkuta | I8: Подтверждено | K8: Активен | L8: Проверено 02.09.2026: доступен. | M8: =IFERROR(__xludf.DUMMYFUNCTION("IF(COUNTA(A8:L8)=0,"""",IFS(AND(H8<>"""",COUNTIF($H$6:$H$504,H8)>1),""Ошибка: повтор URL"",OR(A8="""",B8="""",C8="""",D8="""",E8="""",F8="""",G8="""",H8="""",K8=""""),""Ошибка: обязательные поля"",NOT(REGEXMATCH(H8,""^https?://[^ /]+"")),""Ошибка: некорре"&"ктная ссылка"",COUNTIF('Справочники'!$A$4:$A$24,C8)=0,""Ошибка: территория вне справочника"",K8=""Недоступен"",""Ошибка: ссылка недоступна"",E8=""Неофициальный источник"",IF(K8=""Активен"",""Готово"",""Проверить: активность""),I8<>""Подтверждено"",""Прове"&"рить: официальность / комментарий"",K8<>""Активен"",""Проверить: активность"",AND(ISNUMBER(J8),J8<TODAY()-30),""Проверить: публикации старше 30 дней"",TRUE,""Готово""))"),"Готово") -> Готово
A9: Максим | B9: 46267 | C9: Республика Коми | D9: Правительство Республики Коми | E9: Региональный орган власти | F9: Telegram | G9: Команда Республики Коми | H9: https://t.me/komanda_komi | I9: Подтверждено | K9: Активен | L9: Проверено 02.09.2026: доступен. | M9: =IFERROR(__xludf.DUMMYFUNCTION("IF(COUNTA(A9:L9)=0,"""",IFS(AND(H9<>"""",COUNTIF($H$6:$H$504,H9)>1),""Ошибка: повтор URL"",OR(A9="""",B9="""",C9="""",D9="""",E9="""",F9="""",G9="""",H9="""",K9=""""),""Ошибка: обязательные поля"",NOT(REGEXMATCH(H9,""^https?://[^ /]+"")),""Ошибка: некорре"&"ктная ссылка"",COUNTIF('Справочники'!$A$4:$A$24,C9)=0,""Ошибка: территория вне справочника"",K9=""Недоступен"",""Ошибка: ссылка недоступна"",E9=""Неофициальный источник"",IF(K9=""Активен"",""Готово"",""Проверить: активность""),I9<>""Подтверждено"",""Прове"&"рить: официальность / комментарий"",K9<>""Активен"",""Проверить: активность"",AND(ISNUMBER(J9),J9<TODAY()-30),""Проверить: публикации старше 30 дней"",TRUE,""Готово""))"),"Готово") -> Готово
A10: Максим | B10: 46267 | C10: Сыктывкар | D10: Максим Мартышин | E10: Глава муниципалитета | F10: Telegram | G10: Максим Мартышин | H10: https://t.me/maximmart2903 | I10: Подтверждено | K10: Активен | L10: Проверено 02.09.2026: доступен. | M10: =IFERROR(__xludf.DUMMYFUNCTION("IF(COUNTA(A10:L10)=0,"""",IFS(AND(H10<>"""",COUNTIF($H$6:$H$504,H10)>1),""Ошибка: повтор URL"",OR(A10="""",B10="""",C10="""",D10="""",E10="""",F10="""",G10="""",H10="""",K10=""""),""Ошибка: обязательные поля"",NOT(REGEXMATCH(H10,""^https?://[^ /]+"")),""О"&"шибка: некорректная ссылка"",COUNTIF('Справочники'!$A$4:$A$24,C10)=0,""Ошибка: территория вне справочника"",K10=""Недоступен"",""Ошибка: ссылка недоступна"",E10=""Неофициальный источник"",IF(K10=""Активен"",""Готово"",""Проверить: активность""),I10<>""Под"&"тверждено"",""Проверить: официальность / комментарий"",K10<>""Активен"",""Проверить: активность"",AND(ISNUMBER(J10),J10<TODAY()-30),""Проверить: публикации старше 30 дней"",TRUE,""Готово""))"),"Готово") -> Готово
A11: Максим | B11: 46267 | C11: Республика Коми | D11: Министерство здравоохранения Республики Коми | E11: Региональный орган власти | F11: Telegram | G11: Минздрав Коми | H11: https://t.me/minzdravkomi | I11: Подтверждено | K11: Активен | L11: Проверено 02.09.2026: доступен. | M11: =IFERROR(__xludf.DUMMYFUNCTION("IF(COUNTA(A11:L11)=0,"""",IFS(AND(H11<>"""",COUNTIF($H$6:$H$504,H11)>1),""Ошибка: повтор URL"",OR(A11="""",B11="""",C11="""",D11="""",E11="""",F11="""",G11="""",H11="""",K11=""""),""Ошибка: обязательные поля"",NOT(REGEXMATCH(H11,""^https?://[^ /]+"")),""О"&"шибка: некорректная ссылка"",COUNTIF('Справочники'!$A$4:$A$24,C11)=0,""Ошибка: территория вне справочника"",K11=""Недоступен"",""Ошибка: ссылка недоступна"",E11=""Неофициальный источник"",IF(K11=""Активен"",""Готово"",""Проверить: активность""),I11<>""Под"&"тверждено"",""Проверить: официальность / комментарий"",K11<>""Активен"",""Проверить: активность"",AND(ISNUMBER(J11),J11<TODAY()-30),""Проверить: публикации старше 30 дней"",TRUE,""Готово""))"),"Готово") -> Готово
A12: Максим | B12: 46267 | C12: Республика Коми | D12: Министерство образования и науки Республики Коми | E12: Региональный орган власти | F12: Telegram | G12: Минобрнауки Коми | H12: https://t.me/komiedu | I12: Подтверждено | K12: Активен | L12: Проверено 02.09.2026: доступен. | M12: =IFERROR(__xludf.DUMMYFUNCTION("IF(COUNTA(A12:L12)=0,"""",IFS(AND(H12<>"""",COUNTIF($H$6:$H$504,H12)>1),""Ошибка: повтор URL"",OR(A12="""",B12="""",C12="""",D12="""",E12="""",F12="""",G12="""",H12="""",K12=""""),""Ошибка: обязательные поля"",NOT(REGEXMATCH(H12,""^https?://[^ /]+"")),""О"&"шибка: некорректная ссылка"",COUNTIF('Справочники'!$A$4:$A$24,C12)=0,""Ошибка: территория вне справочника"",K12=""Недоступен"",""Ошибка: ссылка недоступна"",E12=""Неофициальный источник"",IF(K12=""Активен"",""Готово"",""Проверить: активность""),I12<>""Под"&"тверждено"",""Проверить: официальность / комментарий"",K12<>""Активен"",""Проверить: активность"",AND(ISNUMBER(J12),J12<TODAY()-30),""Проверить: публикации старше 30 дней"",TRUE,""Готово""))"),"Готово") -> Готово
A13: Максим | B13: 46267 | C13: Республика Коми | D13: Министерство природных ресурсов и охраны окружающей среды Республики Коми | E13: Региональный орган власти | F13: Telegram | G13: Минприроды Коми | H13: https://t.me/mprkomi | I13: Подтверждено | K13: Активен | L13: Проверено 02.09.2026: доступен. | M13: =IFERROR(__xludf.DUMMYFUNCTION("IF(COUNTA(A13:L13)=0,"""",IFS(AND(H13<>"""",COUNTIF($H$6:$H$504,H13)>1),""Ошибка: повтор URL"",OR(A13="""",B13="""",C13="""",D13="""",E13="""",F13="""",G13="""",H13="""",K13=""""),""Ошибка: обязательные поля"",NOT(REGEXMATCH(H13,""^https?://[^ /]+"")),""О"&"шибка: некорректная ссылка"",COUNTIF('Справочники'!$A$4:$A$24,C13)=0,""Ошибка: территория вне справочника"",K13=""Недоступен"",""Ошибка: ссылка недоступна"",E13=""Неофициальный источник"",IF(K13=""Активен"",""Готово"",""Проверить: активность""),I13<>""Под"&"тверждено"",""Проверить: официальность / комментарий"",K13<>""Активен"",""Проверить: активность"",AND(ISNUMBER(J13),J13<TODAY()-30),""Проверить: публикации старше 30 дней"",TRUE,""Готово""))"),"Готово") -> Готово
A14: Максим | B14: 46267 | C14: Сыктывкар | D14: Ольга Сотникова — ректор СГУ им. Питирима Сорокина | E14: Муниципальное учреждение | F14: Telegram | G14: Ольга Сотникова | Ректор СГУ им. Питирима Сорокина | H14: https://t.me/rectorSYKTSU | I14: Подтверждено | K14: Активен | L14: Проверено 02.09.2026: доступен. | M14: =IFERROR(__xludf.DUMMYFUNCTION("IF(COUNTA(A14:L14)=0,"""",IFS(AND(H14<>"""",COUNTIF($H$6:$H$504,H14)>1),""Ошибка: повтор URL"",OR(A14="""",B14="""",C14="""",D14="""",E14="""",F14="""",G14="""",H14="""",K14=""""),""Ошибка: обязательные поля"",NOT(REGEXMATCH(H14,""^https?://[^ /]+"")),""О"&"шибка: некорректная ссылка"",COUNTIF('Справочники'!$A$4:$A$24,C14)=0,""Ошибка: территория вне справочника"",K14=""Недоступен"",""Ошибка: ссылка недоступна"",E14=""Неофициальный источник"",IF(K14=""Активен"",""Готово"",""Проверить: активность""),I14<>""Под"&"тверждено"",""Проверить: официальность / комментарий"",K14<>""Активен"",""Проверить: активность"",AND(ISNUMBER(J14),J14<TODAY()-30),""Проверить: публикации старше 30 дней"",TRUE,""Готово""))"),"Готово") -> Готово
A15: Максим | B15: 46267 | C15: Ухта | D15: Газпром трансгаз Ухта | E15: Другое официальное | F15: Telegram | G15: ООО «Газпром трансгаз Ухта» | H15: https://t.me/gazprom_gtukhta | I15: Подтверждено | K15: Активен | L15: Проверено 02.09.2026: доступен. | M15: =IFERROR(__xludf.DUMMYFUNCTION("IF(COUNTA(A15:L15)=0,"""",IFS(AND(H15<>"""",COUNTIF($H$6:$H$504,H15)>1),""Ошибка: повтор URL"",OR(A15="""",B15="""",C15="""",D15="""",E15="""",F15="""",G15="""",H15="""",K15=""""),""Ошибка: обязательные поля"",NOT(REGEXMATCH(H15,""^https?://[^ /]+"")),""О"&"шибка: некорректная ссылка"",COUNTIF('Справочники'!$A$4:$A$24,C15)=0,""Ошибка: территория вне справочника"",K15=""Недоступен"",""Ошибка: ссылка недоступна"",E15=""Неофициальный источник"",IF(K15=""Активен"",""Готово"",""Проверить: активность""),I15<>""Под"&"тверждено"",""Проверить: официальность / комментарий"",K15<>""Активен"",""Проверить: активность"",AND(ISNUMBER(J15),J15<TODAY()-30),""Проверить: публикации старше 30 дней"",TRUE,""Готово""))"),"Готово") -> Готово
A16: Максим | B16: 46267 | C16: Республика Коми | D16: МВД по Республике Коми | E16: Региональный орган власти | F16: Telegram | G16: Полиция Коми | H16: https://t.me/mvd_komi | I16: Подтверждено | K16: Активен | L16: Проверено 02.09.2026: доступен. | M16: =IFERROR(__xludf.DUMMYFUNCTION("IF(COUNTA(A16:L16)=0,"""",IFS(AND(H16<>"""",COUNTIF($H$6:$H$504,H16)>1),""Ошибка: повтор URL"",OR(A16="""",B16="""",C16="""",D16="""",E16="""",F16="""",G16="""",H16="""",K16=""""),""Ошибка: обязательные поля"",NOT(REGEXMATCH(H16,""^https?://[^ /]+"")),""О"&"шибка: некорректная ссылка"",COUNTIF('Справочники'!$A$4:$A$24,C16)=0,""Ошибка: территория вне справочника"",K16=""Недоступен"",""Ошибка: ссылка недоступна"",E16=""Неофициальный источник"",IF(K16=""Активен"",""Готово"",""Проверить: активность""),I16<>""Под"&"тверждено"",""Проверить: официальность / комментарий"",K16<>""Активен"",""Проверить: активность"",AND(ISNUMBER(J16),J16<TODAY()-30),""Проверить: публикации старше 30 дней"",TRUE,""Готово""))"),"Готово") -> Готово
A17: Максим | B17: 46267 | C17: Республика Коми | D17: Прокуратура Республики Коми | E17: Региональный орган власти | F17: Telegram | G17: Прокуратура Республики Коми | H17: https://t.me/komiproc | I17: Подтверждено | K17: Активен | L17: Проверено 02.09.2026: доступен. | M17: =IFERROR(__xludf.DUMMYFUNCTION("IF(COUNTA(A17:L17)=0,"""",IFS(AND(H17<>"""",COUNTIF($H$6:$H$504,H17)>1),""Ошибка: повтор URL"",OR(A17="""",B17="""",C17="""",D17="""",E17="""",F17="""",G17="""",H17="""",K17=""""),""Ошибка: обязательные поля"",NOT(REGEXMATCH(H17,""^https?://[^ /]+"")),""О"&"шибка: некорректная ссылка"",COUNTIF('Справочники'!$A$4:$A$24,C17)=0,""Ошибка: территория вне справочника"",K17=""Недоступен"",""Ошибка: ссылка недоступна"",E17=""Неофициальный источник"",IF(K17=""Активен"",""Готово"",""Проверить: активность""),I17<>""Под"&"тверждено"",""Проверить: официальность / комментарий"",K17<>""Активен"",""Проверить: активность"",AND(ISNUMBER(J17),J17<TODAY()-30),""Проверить: публикации старше 30 дней"",TRUE,""Готово""))"),"Готово") -> Готово
A18: Максим | B18: 46267 | C18: Республика Коми | D18: СУ СК России по Республике Коми | E18: Региональный орган власти | F18: Telegram | G18: СУ СК России по Республике Коми | H18: https://t.me/su_skr11 | I18: Подтверждено | K18: Активен | L18: Проверено 02.09.2026: доступен. | M18: =IFERROR(__xludf.DUMMYFUNCTION("IF(COUNTA(A18:L18)=0,"""",IFS(AND(H18<>"""",COUNTIF($H$6:$H$504,H18)>1),""Ошибка: повтор URL"",OR(A18="""",B18="""",C18="""",D18="""",E18="""",F18="""",G18="""",H18="""",K18=""""),""Ошибка: обязательные поля"",NOT(REGEXMATCH(H18,""^https?://[^ /]+"")),""О"&"шибка: некорректная ссылка"",COUNTIF('Справочники'!$A$4:$A$24,C18)=0,""Ошибка: территория вне справочника"",K18=""Недоступен"",""Ошибка: ссылка недоступна"",E18=""Неофициальный источник"",IF(K18=""Активен"",""Готово"",""Проверить: активность""),I18<>""Под"&"тверждено"",""Проверить: официальность / комментарий"",K18<>""Активен"",""Проверить: активность"",AND(ISNUMBER(J18),J18<TODAY()-30),""Проверить: публикации старше 30 дней"",TRUE,""Готово""))"),"Готово") -> Готово
A19: Максим | B19: 46267 | C19: Ухта | D19: Ухтинский государственный технический университет | E19: Муниципальное учреждение | F19: Telegram | G19: УГТУ: Актуальное | H19: https://t.me/ugtu_aktualnoe | I19: Подтверждено | K19: Активен | L19: Проверено 02.09.2026: доступен. | M19: =IFERROR(__xludf.DUMMYFUNCTION("IF(COUNTA(A19:L19)=0,"""",IFS(AND(H19<>"""",COUNTIF($H$6:$H$504,H19)>1),""Ошибка: повтор URL"",OR(A19="""",B19="""",C19="""",D19="""",E19="""",F19="""",G19="""",H19="""",K19=""""),""Ошибка: обязательные поля"",NOT(REGEXMATCH(H19,""^https?://[^ /]+"")),""О"&"шибка: некорректная ссылка"",COUNTIF('Справочники'!$A$4:$A$24,C19)=0,""Ошибка: территория вне справочника"",K19=""Недоступен"",""Ошибка: ссылка недоступна"",E19=""Неофициальный источник"",IF(K19=""Активен"",""Готово"",""Проверить: активность""),I19<>""Под"&"тверждено"",""Проверить: официальность / комментарий"",K19<>""Активен"",""Проверить: активность"",AND(ISNUMBER(J19),J19<TODAY()-30),""Проверить: публикации старше 30 дней"",TRUE,""Готово""))"),"Готово") -> Готово
A20: Максим | B20: 46267 | C20: Сыктывкар | D20: ВСыке | E20: Неофициальный источник | F20: Telegram | G20: ВСыке | H20: https://t.me/v_syke | I20: Не подтверждено | K20: Активен | L20: Не заполнено: Тип источника. | M20: =IFERROR(__xludf.DUMMYFUNCTION("IF(COUNTA(A20:L20)=0,"""",IFS(AND(H20<>"""",COUNTIF($H$6:$H$504,H20)>1),""Ошибка: повтор URL"",OR(A20="""",B20="""",C20="""",D20="""",E20="""",F20="""",G20="""",H20="""",K20=""""),""Ошибка: обязательные поля"",NOT(REGEXMATCH(H20,""^https?://[^ /]+"")),""О"&"шибка: некорректная ссылка"",COUNTIF('Справочники'!$A$4:$A$24,C20)=0,""Ошибка: территория вне справочника"",K20=""Недоступен"",""Ошибка: ссылка недоступна"",E20=""Неофициальный источник"",IF(K20=""Активен"",""Готово"",""Проверить: активность""),I20<>""Под"&"тверждено"",""Проверить: официальность / комментарий"",K20<>""Активен"",""Проверить: активность"",AND(ISNUMBER(J20),J20<TODAY()-30),""Проверить: публикации старше 30 дней"",TRUE,""Готово""))"),"Готово") -> Готово
A21: Максим | B21: 46267 | C21: Республика Коми | D21: Олег Михайлов — ГОЛОС РЕСПУБЛИКИ | E21: Совет / представительный орган | F21: Telegram | G21: ГОЛОС РЕСПУБЛИКИ | H21: https://t.me/rkomivoice | I21: Подтверждено | K21: Активен | L21: Не заполнено: Муниципалитет. | M21: =IFERROR(__xludf.DUMMYFUNCTION("IF(COUNTA(A21:L21)=0,"""",IFS(AND(H21<>"""",COUNTIF($H$6:$H$504,H21)>1),""Ошибка: повтор URL"",OR(A21="""",B21="""",C21="""",D21="""",E21="""",F21="""",G21="""",H21="""",K21=""""),""Ошибка: обязательные поля"",NOT(REGEXMATCH(H21,""^https?://[^ /]+"")),""О"&"шибка: некорректная ссылка"",COUNTIF('Справочники'!$A$4:$A$24,C21)=0,""Ошибка: территория вне справочника"",K21=""Недоступен"",""Ошибка: ссылка недоступна"",E21=""Неофициальный источник"",IF(K21=""Активен"",""Готово"",""Проверить: активность""),I21<>""Под"&"тверждено"",""Проверить: официальность / комментарий"",K21<>""Активен"",""Проверить: активность"",AND(ISNUMBER(J21),J21<TODAY()-30),""Проверить: публикации старше 30 дней"",TRUE,""Готово""))"),"Готово") -> Готово
A22: Максим | B22: 46267 | C22: Республика Коми | D22: Ростислав Гольдштейн | E22: Глава муниципалитета | F22: Telegram | G22: Гольдштейн | Республика Коми | H22: https://t.me/goldshtein_komi | I22: Подтверждено | K22: Активен | L22: Не заполнено: Муниципалитет, Тип источника. | M22: =IFERROR(__xludf.DUMMYFUNCTION("IF(COUNTA(A22:L22)=0,"""",IFS(AND(H22<>"""",COUNTIF($H$6:$H$504,H22)>1),""Ошибка: повтор URL"",OR(A22="""",B22="""",C22="""",D22="""",E22="""",F22="""",G22="""",H22="""",K22=""""),""Ошибка: обязательные поля"",NOT(REGEXMATCH(H22,""^https?://[^ /]+"")),""О"&"шибка: некорректная ссылка"",COUNTIF('Справочники'!$A$4:$A$24,C22)=0,""Ошибка: территория вне справочника"",K22=""Недоступен"",""Ошибка: ссылка недоступна"",E22=""Неофициальный источник"",IF(K22=""Активен"",""Готово"",""Проверить: активность""),I22<>""Под"&"тверждено"",""Проверить: официальность / комментарий"",K22<>""Активен"",""Проверить: активность"",AND(ISNUMBER(J22),J22<TODAY()-30),""Проверить: публикации старше 30 дней"",TRUE,""Готово""))"),"Готово") -> Готово
A23: Максим | B23: 46267 | C23: Республика Коми | D23: Коми — это Ж | E23: Неофициальный источник | F23: Telegram | G23: Коми - это Ж 🇷🇺 | H23: https://t.me/komivkomi | I23: Не подтверждено | K23: Активен | L23: Не заполнено: Муниципалитет, Тип источника. | M23: =IFERROR(__xludf.DUMMYFUNCTION("IF(COUNTA(A23:L23)=0,"""",IFS(AND(H23<>"""",COUNTIF($H$6:$H$504,H23)>1),""Ошибка: повтор URL"",OR(A23="""",B23="""",C23="""",D23="""",E23="""",F23="""",G23="""",H23="""",K23=""""),""Ошибка: обязательные поля"",NOT(REGEXMATCH(H23,""^https?://[^ /]+"")),""О"&"шибка: некорректная ссылка"",COUNTIF('Справочники'!$A$4:$A$24,C23)=0,""Ошибка: территория вне справочника"",K23=""Недоступен"",""Ошибка: ссылка недоступна"",E23=""Неофициальный источник"",IF(K23=""Активен"",""Готово"",""Проверить: активность""),I23<>""Под"&"тверждено"",""Проверить: официальность / комментарий"",K23<>""Активен"",""Проверить: активность"",AND(ISNUMBER(J23),J23<TODAY()-30),""Проверить: публикации старше 30 дней"",TRUE,""Готово""))"),"Готово") -> Готово
A24: Максим | B24: 46267 | C24: Республика Коми | D24: Коми Тещи и Неизвестные Отцы | E24: Неофициальный источник | F24: Telegram | G24: Коми Тещи и Неизвестные Отцы | H24: https://t.me/komitesha | I24: Не подтверждено | K24: Активен | L24: Не заполнено: Муниципалитет, Тип источника. | M24: =IFERROR(__xludf.DUMMYFUNCTION("IF(COUNTA(A24:L24)=0,"""",IFS(AND(H24<>"""",COUNTIF($H$6:$H$504,H24)>1),""Ошибка: повтор URL"",OR(A24="""",B24="""",C24="""",D24="""",E24="""",F24="""",G24="""",H24="""",K24=""""),""Ошибка: обязательные поля"",NOT(REGEXMATCH(H24,""^https?://[^ /]+"")),""О"&"шибка: некорректная ссылка"",COUNTIF('Справочники'!$A$4:$A$24,C24)=0,""Ошибка: территория вне справочника"",K24=""Недоступен"",""Ошибка: ссылка недоступна"",E24=""Неофициальный источник"",IF(K24=""Активен"",""Готово"",""Проверить: активность""),I24<>""Под"&"тверждено"",""Проверить: официальность / комментарий"",K24<>""Активен"",""Проверить: активность"",AND(ISNUMBER(J24),J24<TODAY()-30),""Проверить: публикации старше 30 дней"",TRUE,""Готово""))"),"Готово") -> Готово
A25: Максим | B25: 46267 | C25: Республика Коми | D25: Комиинформ | E25: Официальная пресс-служба | F25: Telegram | G25: Комиинформ | H25: https://t.me/komiinform | I25: Подтверждено | K25: Активен | L25: Повтор URL: строки 30, 299, 307, 309. Не заполнено: Муниципалитет. | M25: =IFERROR(__xludf.DUMMYFUNCTION("IF(COUNTA(A25:L25)=0,"""",IFS(AND(H25<>"""",COUNTIF($H$6:$H$504,H25)>1),""Ошибка: повтор URL"",OR(A25="""",B25="""",C25="""",D25="""",E25="""",F25="""",G25="""",H25="""",K25=""""),""Ошибка: обязательные поля"",NOT(REGEXMATCH(H25,""^https?://[^ /]+"")),""О"&"шибка: некорректная ссылка"",COUNTIF('Справочники'!$A$4:$A$24,C25)=0,""Ошибка: территория вне справочника"",K25=""Недоступен"",""Ошибка: ссылка недоступна"",E25=""Неофициальный источник"",IF(K25=""Активен"",""Готово"",""Проверить: активность""),I25<>""Под"&"тверждено"",""Проверить: официальность / комментарий"",K25<>""Активен"",""Проверить: активность"",AND(ISNUMBER(J25),J25<TODAY()-30),""Проверить: публикации старше 30 дней"",TRUE,""Готово""))"),"Готово") -> Готово
A26: Максим | B26: 46267 | C26: Сыктывкар | D26: КомиСлив | E26: Неофициальный источник | F26: Telegram | G26: КомиСлив | H26: https://t.me/my_sykt | I26: Не подтверждено | K26: Активен | L26: Не заполнено: Тип источника. | M26: =IFERROR(__xludf.DUMMYFUNCTION("IF(COUNTA(A26:L26)=0,"""",IFS(AND(H26<>"""",COUNTIF($H$6:$H$504,H26)>1),""Ошибка: повтор URL"",OR(A26="""",B26="""",C26="""",D26="""",E26="""",F26="""",G26="""",H26="""",K26=""""),""Ошибка: обязательные поля"",NOT(REGEXMATCH(H26,""^https?://[^ /]+"")),""О"&"шибка: некорректная ссылка"",COUNTIF('Справочники'!$A$4:$A$24,C26)=0,""Ошибка: территория вне справочника"",K26=""Недоступен"",""Ошибка: ссылка недоступна"",E26=""Неофициальный источник"",IF(K26=""Активен"",""Готово"",""Проверить: активность""),I26<>""Под"&"тверждено"",""Проверить: официальность / комментарий"",K26<>""Активен"",""Проверить: активность"",AND(ISNUMBER(J26),J26<TODAY()-30),""Проверить: публикации старше 30 дней"",TRUE,""Готово""))"),"Готово") -> Готово
A27: Максим | B27: 46267 | C27: Республика Коми | D27: Коми Телега | E27: Неофициальный источник | F27: Telegram | G27: КOMИ ТЕЛЕГА. Что видим - то поём | H27: https://t.me/komitelega | I27: Не подтверждено | K27: Активен | L27: Не заполнено: Муниципалитет, Тип источника. | M27: =IFERROR(__xludf.DUMMYFUNCTION("IF(COUNTA(A27:L27)=0,"""",IFS(AND(H27<>"""",COUNTIF($H$6:$H$504,H27)>1),""Ошибка: повтор URL"",OR(A27="""",B27="""",C27="""",D27="""",E27="""",F27="""",G27="""",H27="""",K27=""""),""Ошибка: обязательные поля"",NOT(REGEXMATCH(H27,""^https?://[^ /]+"")),""О"&"шибка: некорректная ссылка"",COUNTIF('Справочники'!$A$4:$A$24,C27)=0,""Ошибка: территория вне справочника"",K27=""Недоступен"",""Ошибка: ссылка недоступна"",E27=""Неофициальный источник"",IF(K27=""Активен"",""Готово"",""Проверить: активность""),I27<>""Под"&"тверждено"",""Проверить: официальность / комментарий"",K27<>""Активен"",""Проверить: активность"",AND(ISNUMBER(J27),J27<TODAY()-30),""Проверить: публикации старше 30 дней"",TRUE,""Готово""))"),"Готово") -> Готово
A28: Максим | B28: 46267 | C28: Ухта | D28: Марина Метелёва | E28: Глава муниципалитета | F28: Telegram | G28: Марина Метелева | H28: https://t.me/marina_meteleva_uhta | I28: Подтверждено | K28: Активен | L28: Не заполнено: Название. | M28: =IFERROR(__xludf.DUMMYFUNCTION("IF(COUNTA(A28:L28)=0,"""",IFS(AND(H28<>"""",COUNTIF($H$6:$H$504,H28)>1),""Ошибка: повтор URL"",OR(A28="""",B28="""",C28="""",D28="""",E28="""",F28="""",G28="""",H28="""",K28=""""),""Ошибка: обязательные поля"",NOT(REGEXMATCH(H28,""^https?://[^ /]+"")),""О"&"шибка: некорректная ссылка"",COUNTIF('Справочники'!$A$4:$A$24,C28)=0,""Ошибка: территория вне справочника"",K28=""Недоступен"",""Ошибка: ссылка недоступна"",E28=""Неофициальный источник"",IF(K28=""Активен"",""Готово"",""Проверить: активность""),I28<>""Под"&"тверждено"",""Проверить: официальность / комментарий"",K28<>""Активен"",""Проверить: активность"",AND(ISNUMBER(J28),J28<TODAY()-30),""Проверить: публикации старше 30 дней"",TRUE,""Готово""))"),"Готово") -> Готово
A29: Максим | B29: 46267 | C29: Ухта | D29: Мария Бутина | E29: Совет / представительный орган | F29: Telegram | G29: Мария Бутина | H29: https://t.me/mariabutina | I29: Подтверждено | K29: Активен | L29: Не заполнено: Муниципалитет. | M29: =IFERROR(__xludf.DUMMYFUNCTION("IF(COUNTA(A29:L29)=0,"""",IFS(AND(H29<>"""",COUNTIF($H$6:$H$504,H29)>1),""Ошибка: повтор URL"",OR(A29="""",B29="""",C29="""",D29="""",E29="""",F29="""",G29="""",H29="""",K29=""""),""Ошибка: обязательные поля"",NOT(REGEXMATCH(H29,""^https?://[^ /]+"")),""О"&"шибка: некорректная ссылка"",COUNTIF('Справочники'!$A$4:$A$24,C29)=0,""Ошибка: территория вне справочника"",K29=""Недоступен"",""Ошибка: ссылка недоступна"",E29=""Неофициальный источник"",IF(K29=""Активен"",""Готово"",""Проверить: активность""),I29<>""Под"&"тверждено"",""Проверить: официальность / комментарий"",K29<>""Активен"",""Проверить: активность"",AND(ISNUMBER(J29),J29<TODAY()-30),""Проверить: публикации старше 30 дней"",TRUE,""Готово""))"),"Готово") -> Готово
A30: Максим | B30: 46267 | C30: Республика Коми | D30: Новая Республика | E30: Неофициальный источник | F30: Telegram | G30: Новая Республика | H30: https://t.me/nrkomi | I30: Не подтверждено | K30: Активен | L30: Не заполнено: Муниципалитет, Тип источника. | M30: =IFERROR(__xludf.DUMMYFUNCTION("IF(COUNTA(A30:L30)=0,"""",IFS(AND(H30<>"""",COUNTIF($H$6:$H$504,H30)>1),""Ошибка: повтор URL"",OR(A30="""",B30="""",C30="""",D30="""",E30="""",F30="""",G30="""",H30="""",K30=""""),""Ошибка: обязательные поля"",NOT(REGEXMATCH(H30,""^https?://[^ /]+"")),""О"&"шибка: некорректная ссылка"",COUNTIF('Справочники'!$A$4:$A$24,C30)=0,""Ошибка: территория вне справочника"",K30=""Недоступен"",""Ошибка: ссылка недоступна"",E30=""Неофициальный источник"",IF(K30=""Активен"",""Готово"",""Проверить: активность""),I30<>""Под"&"тверждено"",""Проверить: официальность / комментарий"",K30<>""Активен"",""Проверить: активность"",AND(ISNUMBER(J30),J30<TODAY()-30),""Проверить: публикации старше 30 дней"",TRUE,""Готово""))"),"Готово") -> Готово
A31: Максим | B31: 46267 | C31: Сыктывкар | D31: Новости Сыктывкара и Коми | E31: Неофициальный источник | F31: Telegram | G31: Новости Сыктывкара и Коми | H31: https://t.me/siktivkar_smi | I31: Не подтверждено | K31: Активен | L31: Не заполнено: Тип источника. | M31: =IFERROR(__xludf.DUMMYFUNCTION("IF(COUNTA(A31:L31)=0,"""",IFS(AND(H31<>"""",COUNTIF($H$6:$H$504,H31)>1),""Ошибка: повтор URL"",OR(A31="""",B31="""",C31="""",D31="""",E31="""",F31="""",G31="""",H31="""",K31=""""),""Ошибка: обязательные поля"",NOT(REGEXMATCH(H31,""^https?://[^ /]+"")),""О"&"шибка: некорректная ссылка"",COUNTIF('Справочники'!$A$4:$A$24,C31)=0,""Ошибка: территория вне справочника"",K31=""Недоступен"",""Ошибка: ссылка недоступна"",E31=""Неофициальный источник"",IF(K31=""Активен"",""Готово"",""Проверить: активность""),I31<>""Под"&"тверждено"",""Проверить: официальность / комментарий"",K31<>""Активен"",""Проверить: активность"",AND(ISNUMBER(J31),J31<TODAY()-30),""Проверить: публикации старше 30 дней"",TRUE,""Готово""))"),"Готово") -> Готово
A32: Максим | B32: 46267 | C32: Республика Коми | D32: ПЕСЕЦ | E32: Неофициальный источник | F32: Telegram | G32: ПЕСЕЦ | H32: https://t.me/pececc | I32: Не подтверждено | K32: Активен | L32: Не заполнено: Муниципалитет, Тип источника. | M32: =IFERROR(__xludf.DUMMYFUNCTION("IF(COUNTA(A32:L32)=0,"""",IFS(AND(H32<>"""",COUNTIF($H$6:$H$504,H32)>1),""Ошибка: повтор URL"",OR(A32="""",B32="""",C32="""",D32="""",E32="""",F32="""",G32="""",H32="""",K32=""""),""Ошибка: обязательные поля"",NOT(REGEXMATCH(H32,""^https?://[^ /]+"")),""О"&"шибка: некорректная ссылка"",COUNTIF('Справочники'!$A$4:$A$24,C32)=0,""Ошибка: территория вне справочника"",K32=""Недоступен"",""Ошибка: ссылка недоступна"",E32=""Неофициальный источник"",IF(K32=""Активен"",""Готово"",""Проверить: активность""),I32<>""Под"&"тверждено"",""Проверить: официальность / комментарий"",K32<>""Активен"",""Проверить: активность"",AND(ISNUMBER(J32),J32<TODAY()-30),""Проверить: публикации старше 30 дней"",TRUE,""Готово""))"),"Готово") -> Готово
A33: Максим | B33: 46267 | C33: Республика Коми | D33: ПолитКоми | E33: Неофициальный источник | F33: Telegram | G33: ПолитКоми | H33: https://t.me/northKomi | I33: Не подтверждено | K33: Активен | L33: Не заполнено: Муниципалитет, Тип источника. | M33: =IFERROR(__xludf.DUMMYFUNCTION("IF(COUNTA(A33:L33)=0,"""",IFS(AND(H33<>"""",COUNTIF($H$6:$H$504,H33)>1),""Ошибка: повтор URL"",OR(A33="""",B33="""",C33="""",D33="""",E33="""",F33="""",G33="""",H33="""",K33=""""),""Ошибка: обязательные поля"",NOT(REGEXMATCH(H33,""^https?://[^ /]+"")),""О"&"шибка: некорректная ссылка"",COUNTIF('Справочники'!$A$4:$A$24,C33)=0,""Ошибка: территория вне справочника"",K33=""Недоступен"",""Ошибка: ссылка недоступна"",E33=""Неофициальный источник"",IF(K33=""Активен"",""Готово"",""Проверить: активность""),I33<>""Под"&"тверждено"",""Проверить: официальность / комментарий"",K33<>""Активен"",""Проверить: активность"",AND(ISNUMBER(J33),J33<TODAY()-30),""Проверить: публикации старше 30 дней"",TRUE,""Готово""))"),"Готово") -> Готово
A34: Максим | B34: 46267 | C34: Сыктывкар | D34: Про Город Сыктывкар | E34: Неофициальный источник | F34: Telegram | G34: Про Город Сыктывкар | Новости | H34: https://t.me/pg11ru | I34: Не подтверждено | K34: Активен | L34: Повтор URL: строки 87, 311. Не заполнено: Тип источника. | M34: =IFERROR(__xludf.DUMMYFUNCTION("IF(COUNTA(A34:L34)=0,"""",IFS(AND(H34<>"""",COUNTIF($H$6:$H$504,H34)>1),""Ошибка: повтор URL"",OR(A34="""",B34="""",C34="""",D34="""",E34="""",F34="""",G34="""",H34="""",K34=""""),""Ошибка: обязательные поля"",NOT(REGEXMATCH(H34,""^https?://[^ /]+"")),""О"&"шибка: некорректная ссылка"",COUNTIF('Справочники'!$A$4:$A$24,C34)=0,""Ошибка: территория вне справочника"",K34=""Недоступен"",""Ошибка: ссылка недоступна"",E34=""Неофициальный источник"",IF(K34=""Активен"",""Готово"",""Проверить: активность""),I34<>""Под"&"тверждено"",""Проверить: официальность / комментарий"",K34<>""Активен"",""Проверить: активность"",AND(ISNUMBER(J34),J34<TODAY()-30),""Проверить: публикации старше 30 дней"",TRUE,""Готово""))"),"Готово") -> Готово
A35: Максим | B35: 46267 | C35: Ухта | D35: Про Город Ухта | E35: Неофициальный источник | F35: Telegram | G35: Про Город Ухта | H35: https://t.me/pgukhta11 | I35: Не подтверждено | K35: Активен | L35: Не заполнено: Тип источника. | M35: =IFERROR(__xludf.DUMMYFUNCTION("IF(COUNTA(A35:L35)=0,"""",IFS(AND(H35<>"""",COUNTIF($H$6:$H$504,H35)>1),""Ошибка: повтор URL"",OR(A35="""",B35="""",C35="""",D35="""",E35="""",F35="""",G35="""",H35="""",K35=""""),""Ошибка: обязательные поля"",NOT(REGEXMATCH(H35,""^https?://[^ /]+"")),""О"&"шибка: некорректная ссылка"",COUNTIF('Справочники'!$A$4:$A$24,C35)=0,""Ошибка: территория вне справочника"",K35=""Недоступен"",""Ошибка: ссылка недоступна"",E35=""Неофициальный источник"",IF(K35=""Активен"",""Готово"",""Проверить: активность""),I35<>""Под"&"тверждено"",""Проверить: официальность / комментарий"",K35<>""Активен"",""Проверить: активность"",AND(ISNUMBER(J35),J35<TODAY()-30),""Проверить: публикации старше 30 дней"",TRUE,""Готово""))"),"Готово") -> Готово
A36: Максим | B36: 46267 | C36: Республика Коми | D36: РВК — Агрегатор новостей | E36: Неофициальный источник | F36: Telegram | G36: РВК - Агрегатор новостей | H36: https://t.me/ranshevcex | I36: Не подтверждено | K36: Активен | L36: Повтор URL: строки 91, 312. Не заполнено: Муниципалитет, Тип источника. | M36: =IFERROR(__xludf.DUMMYFUNCTION("IF(COUNTA(A36:L36)=0,"""",IFS(AND(H36<>"""",COUNTIF($H$6:$H$504,H36)>1),""Ошибка: повтор URL"",OR(A36="""",B36="""",C36="""",D36="""",E36="""",F36="""",G36="""",H36="""",K36=""""),""Ошибка: обязательные поля"",NOT(REGEXMATCH(H36,""^https?://[^ /]+"")),""О"&"шибка: некорректная ссылка"",COUNTIF('Справочники'!$A$4:$A$24,C36)=0,""Ошибка: территория вне справочника"",K36=""Недоступен"",""Ошибка: ссылка недоступна"",E36=""Неофициальный источник"",IF(K36=""Активен"",""Готово"",""Проверить: активность""),I36<>""Под"&"тверждено"",""Проверить: официальность / комментарий"",K36<>""Активен"",""Проверить: активность"",AND(ISNUMBER(J36),J36<TODAY()-30),""Проверить: публикации старше 30 дней"",TRUE,""Готово""))"),"Готово") -> Готово
A37: Максим | B37: 46267 | C37: Республика Коми | D37: Республика Коми | E37: Официальная пресс-служба | F37: Telegram | G37: Республика Коми Z | H37: https://t.me/rkomiru | I37: Подтверждено | K37: Активен | L37: Повтор URL: строки 93, 313. Не заполнено: Муниципалитет, Тип источника. | M37: =IFERROR(__xludf.DUMMYFUNCTION("IF(COUNTA(A37:L37)=0,"""",IFS(AND(H37<>"""",COUNTIF($H$6:$H$504,H37)>1),""Ошибка: повтор URL"",OR(A37="""",B37="""",C37="""",D37="""",E37="""",F37="""",G37="""",H37="""",K37=""""),""Ошибка: обязательные поля"",NOT(REGEXMATCH(H37,""^https?://[^ /]+"")),""О"&"шибка: некорректная ссылка"",COUNTIF('Справочники'!$A$4:$A$24,C37)=0,""Ошибка: территория вне справочника"",K37=""Недоступен"",""Ошибка: ссылка недоступна"",E37=""Неофициальный источник"",IF(K37=""Активен"",""Готово"",""Проверить: активность""),I37<>""Под"&"тверждено"",""Проверить: официальность / комментарий"",K37<>""Активен"",""Проверить: активность"",AND(ISNUMBER(J37),J37<TODAY()-30),""Проверить: публикации старше 30 дней"",TRUE,""Готово""))"),"Готово") -> Готово
A38: Максим | B38: 46267 | C38: Сыктывкар | D38: Станислав Кочев | E38: Совет / представительный орган | F38: Telegram | G38: Станислав Кочев | H38: https://t.me/skochev | I38: Подтверждено | K38: Активен | L38: Не заполнено: Муниципалитет. | M38: =IFERROR(__xludf.DUMMYFUNCTION("IF(COUNTA(A38:L38)=0,"""",IFS(AND(H38<>"""",COUNTIF($H$6:$H$504,H38)>1),""Ошибка: повтор URL"",OR(A38="""",B38="""",C38="""",D38="""",E38="""",F38="""",G38="""",H38="""",K38=""""),""Ошибка: обязательные поля"",NOT(REGEXMATCH(H38,""^https?://[^ /]+"")),""О"&"шибка: некорректная ссылка"",COUNTIF('Справочники'!$A$4:$A$24,C38)=0,""Ошибка: территория вне справочника"",K38=""Недоступен"",""Ошибка: ссылка недоступна"",E38=""Неофициальный источник"",IF(K38=""Активен"",""Готово"",""Проверить: активность""),I38<>""Под"&"тверждено"",""Проверить: официальность / комментарий"",K38<>""Активен"",""Проверить: активность"",AND(ISNUMBER(J38),J38<TODAY()-30),""Проверить: публикации старше 30 дней"",TRUE,""Готово""))"),"Готово") -> Готово
A39: Максим | B39: 46267 | C39: Сыктывкар | D39: Сыктывкар №1 | E39: Неофициальный источник | F39: Telegram | G39: Сыктывкар №1 | H39: https://t.me/syktyvkar01 | I39: Не подтверждено | K39: Активен | L39: Не заполнено: Тип источника. | M39: =IFERROR(__xludf.DUMMYFUNCTION("IF(COUNTA(A39:L39)=0,"""",IFS(AND(H39<>"""",COUNTIF($H$6:$H$504,H39)>1),""Ошибка: повтор URL"",OR(A39="""",B39="""",C39="""",D39="""",E39="""",F39="""",G39="""",H39="""",K39=""""),""Ошибка: обязательные поля"",NOT(REGEXMATCH(H39,""^https?://[^ /]+"")),""О"&"шибка: некорректная ссылка"",COUNTIF('Справочники'!$A$4:$A$24,C39)=0,""Ошибка: территория вне справочника"",K39=""Недоступен"",""Ошибка: ссылка недоступна"",E39=""Неофициальный источник"",IF(K39=""Активен"",""Готово"",""Проверить: активность""),I39<>""Под"&"тверждено"",""Проверить: официальность / комментарий"",K39<>""Активен"",""Проверить: активность"",AND(ISNUMBER(J39),J39<TODAY()-30),""Проверить: публикации старше 30 дней"",TRUE,""Готово""))"),"Готово") -> Готово
A40: Максим | B40: 46267 | C40: Воркута | D40: Ту-ту на Воркуту | E40: Неофициальный источник | F40: Telegram | G40: Ту-ту на Воркуту | H40: https://t.me/tovorkuta | I40: Не подтверждено | K40: Активен | L40: Не заполнено: Тип источника. | M40: =IFERROR(__xludf.DUMMYFUNCTION("IF(COUNTA(A40:L40)=0,"""",IFS(AND(H40<>"""",COUNTIF($H$6:$H$504,H40)>1),""Ошибка: повтор URL"",OR(A40="""",B40="""",C40="""",D40="""",E40="""",F40="""",G40="""",H40="""",K40=""""),""Ошибка: обязательные поля"",NOT(REGEXMATCH(H40,""^https?://[^ /]+"")),""О"&"шибка: некорректная ссылка"",COUNTIF('Справочники'!$A$4:$A$24,C40)=0,""Ошибка: территория вне справочника"",K40=""Недоступен"",""Ошибка: ссылка недоступна"",E40=""Неофициальный источник"",IF(K40=""Активен"",""Готово"",""Проверить: активность""),I40<>""Под"&"тверждено"",""Проверить: официальность / комментарий"",K40<>""Активен"",""Проверить: активность"",AND(ISNUMBER(J40),J40<TODAY()-30),""Проверить: публикации старше 30 дней"",TRUE,""Готово""))"),"Готово") -> Готово
A41: Максим | B41: 46267 | C41: Ухта | D41: Ухо Ухты | E41: Неофициальный источник | F41: Telegram | G41: Ухо Ухты | H41: https://t.me/uhoukhta | I41: Не подтверждено | K41: Активен | L41: Не заполнено: Тип источника. | M41: =IFERROR(__xludf.DUMMYFUNCTION("IF(COUNTA(A41:L41)=0,"""",IFS(AND(H41<>"""",COUNTIF($H$6:$H$504,H41)>1),""Ошибка: повтор URL"",OR(A41="""",B41="""",C41="""",D41="""",E41="""",F41="""",G41="""",H41="""",K41=""""),""Ошибка: обязательные поля"",NOT(REGEXMATCH(H41,""^https?://[^ /]+"")),""О"&"шибка: некорректная ссылка"",COUNTIF('Справочники'!$A$4:$A$24,C41)=0,""Ошибка: территория вне справочника"",K41=""Недоступен"",""Ошибка: ссылка недоступна"",E41=""Неофициальный источник"",IF(K41=""Активен"",""Готово"",""Проверить: активность""),I41<>""Под"&"тверждено"",""Проверить: официальность / комментарий"",K41<>""Активен"",""Проверить: активность"",AND(ISNUMBER(J41),J41<TODAY()-30),""Проверить: публикации старше 30 дней"",TRUE,""Готово""))"),"Готово") -> Готово
...

Sheet Справочники
A1: Служебные справочники — не редактировать
A3: Муниципалитеты | B3: Категории | C3: Платформы | D3: Стадии | E3: Типы источников | F3: Официальность | G3: Активность | H3: Дубли
A4: Воркута | B4: Власть и кадровые решения | C4: Официальный сайт | D4: Анонс | E4: Администрация муниципалитета | F4: Подтверждено | G4: Активен | H4: Нет
A5: Вуктыл | B5: Бюджет и муниципальные финансы | C5: MAX | D5: Решение принято | E5: Глава муниципалитета | F5: Не подтверждено | G5: Неактивен | H5: Да
A6: Ижемский район | B6: Закупки и контракты | C6: ВКонтакте | D6: Финансирование выделено | E6: Совет / представительный орган | F6: Требует проверки | G6: Недоступен | H6: Нужно проверить
A7: Инта | B7: Строительство и инфраструктура | C7: Telegram | D7: Закупка объявлена | E7: Муниципальное учреждение | G7: Требует проверки
A8: Княжпогостский район | B8: ЖКХ и благоустройство | C8: Одноклассники | D8: Работы начаты | E8: Региональный орган власти
A9: Койгородский район | B9: Экономика, бизнес и занятость | C9: Rutube | D9: В процессе | E9: Официальная пресс-служба
A10: Корткеросский район | B10: Социальная сфера | C10: Другое | D10: Завершено / открыто | E10: Другое официальное
A11: Печора | B11: Образование | D11: Перенесено / приостановлено | E11: Неофициальный источник
A12: Прилузский район | B12: Здравоохранение | D12: Проблема / происшествие
A13: Сосногорск | B13: Происшествия и безопасность | D13: Результат
A14: Сыктывдинский район | B14: Экология
A15: Сыктывкар | B15: Обращения и проблемы жителей
A16: Сысольский район | B16: Культура, спорт и туризм
A17: Троицко-Печорский район | B17: Банки и финансовые сервисы
A18: Удорский район | B18: Другое
A19: Усинск
A20: Усть-Вымский район
A21: Усть-Куломский район
A22: Усть-Цилемский район
A23: Ухта
A24: Республика Коми

Sheet Контроль
A1: Контроль покрытия муниципалитетов — служебный лист
A2: Показатели рассчитываются автоматически по основному муниципалитету.
A3: Муниципалитет | B3: Всего источников | C3: Готовых источников | D3: Новостей за 30 дней | E3: Готовых новостей | F3: Нужно проверить | G3: Ошибки
A4: Воркута | B4: =COUNTIF(Источники!$C$6:$C$504,A4) -> 15 | C4: =COUNTIFS(Источники!$C$6:$C$504,A4,Источники!$M$6:$M$504,"Готово") -> 15 | D4: =COUNTIFS(#REF!,A4,#REF!,">="&TODAY()-30) -> #REF! | E4: =COUNTIFS(#REF!,A4,#REF!,"Готово") -> #REF! | F4: =COUNTIFS(#REF!,A4,#REF!,"Проверить*") -> #REF! | G4: =COUNTIFS(#REF!,A4,#REF!,"Ошибка*") -> #REF!
A5: Вуктыл | B5: =COUNTIF(Источники!$C$6:$C$504,A5) -> 3 | C5: =COUNTIFS(Источники!$C$6:$C$504,A5,Источники!$M$6:$M$504,"Готово") -> 3 | D5: =COUNTIFS(#REF!,A5,#REF!,">="&TODAY()-30) -> #REF! | E5: =COUNTIFS(#REF!,A5,#REF!,"Готово") -> #REF! | F5: =COUNTIFS(#REF!,A5,#REF!,"Проверить*") -> #REF! | G5: =COUNTIFS(#REF!,A5,#REF!,"Ошибка*") -> #REF!
A6: Ижемский район | B6: =COUNTIF(Источники!$C$6:$C$504,A6) -> 3 | C6: =COUNTIFS(Источники!$C$6:$C$504,A6,Источники!$M$6:$M$504,"Готово") -> 3 | D6: =COUNTIFS(#REF!,A6,#REF!,">="&TODAY()-30) -> #REF! | E6: =COUNTIFS(#REF!,A6,#REF!,"Готово") -> #REF! | F6: =COUNTIFS(#REF!,A6,#REF!,"Проверить*") -> #REF! | G6: =COUNTIFS(#REF!,A6,#REF!,"Ошибка*") -> #REF!
A7: Инта | B7: =COUNTIF(Источники!$C$6:$C$504,A7) -> 4 | C7: =COUNTIFS(Источники!$C$6:$C$504,A7,Источники!$M$6:$M$504,"Готово") -> 4 | D7: =COUNTIFS(#REF!,A7,#REF!,">="&TODAY()-30) -> #REF! | E7: =COUNTIFS(#REF!,A7,#REF!,"Готово") -> #REF! | F7: =COUNTIFS(#REF!,A7,#REF!,"Проверить*") -> #REF! | G7: =COUNTIFS(#REF!,A7,#REF!,"Ошибка*") -> #REF!
A8: Княжпогостский район | B8: =COUNTIF(Источники!$C$6:$C$504,A8) -> 3 | C8: =COUNTIFS(Источники!$C$6:$C$504,A8,Источники!$M$6:$M$504,"Готово") -> 3 | D8: =COUNTIFS(#REF!,A8,#REF!,">="&TODAY()-30) -> #REF! | E8: =COUNTIFS(#REF!,A8,#REF!,"Готово") -> #REF! | F8: =COUNTIFS(#REF!,A8,#REF!,"Проверить*") -> #REF! | G8: =COUNTIFS(#REF!,A8,#REF!,"Ошибка*") -> #REF!
A9: Койгородский район | B9: =COUNTIF(Источники!$C$6:$C$504,A9) -> 2 | C9: =COUNTIFS(Источники!$C$6:$C$504,A9,Источники!$M$6:$M$504,"Готово") -> 2 | D9: =COUNTIFS(#REF!,A9,#REF!,">="&TODAY()-30) -> #REF! | E9: =COUNTIFS(#REF!,A9,#REF!,"Готово") -> #REF! | F9: =COUNTIFS(#REF!,A9,#REF!,"Проверить*") -> #REF! | G9: =COUNTIFS(#REF!,A9,#REF!,"Ошибка*") -> #REF!
A10: Корткеросский район | B10: =COUNTIF(Источники!$C$6:$C$504,A10) -> 7 | C10: =COUNTIFS(Источники!$C$6:$C$504,A10,Источники!$M$6:$M$504,"Готово") -> 7 | D10: =COUNTIFS(#REF!,A10,#REF!,">="&TODAY()-30) -> #REF! | E10: =COUNTIFS(#REF!,A10,#REF!,"Готово") -> #REF! | F10: =COUNTIFS(#REF!,A10,#REF!,"Проверить*") -> #REF! | G10: =COUNTIFS(#REF!,A10,#REF!,"Ошибка*") -> #REF!
A11: Печора | B11: =COUNTIF(Источники!$C$6:$C$504,A11) -> 16 | C11: =COUNTIFS(Источники!$C$6:$C$504,A11,Источники!$M$6:$M$504,"Готово") -> 16 | D11: =COUNTIFS(#REF!,A11,#REF!,">="&TODAY()-30) -> #REF! | E11: =COUNTIFS(#REF!,A11,#REF!,"Готово") -> #REF! | F11: =COUNTIFS(#REF!,A11,#REF!,"Проверить*") -> #REF! | G11: =COUNTIFS(#REF!,A11,#REF!,"Ошибка*") -> #REF!
A12: Прилузский район | B12: =COUNTIF(Источники!$C$6:$C$504,A12) -> 3 | C12: =COUNTIFS(Источники!$C$6:$C$504,A12,Источники!$M$6:$M$504,"Готово") -> 2 | D12: =COUNTIFS(#REF!,A12,#REF!,">="&TODAY()-30) -> #REF! | E12: =COUNTIFS(#REF!,A12,#REF!,"Готово") -> #REF! | F12: =COUNTIFS(#REF!,A12,#REF!,"Проверить*") -> #REF! | G12: =COUNTIFS(#REF!,A12,#REF!,"Ошибка*") -> #REF!
A13: Сосногорск | B13: =COUNTIF(Источники!$C$6:$C$504,A13) -> 17 | C13: =COUNTIFS(Источники!$C$6:$C$504,A13,Источники!$M$6:$M$504,"Готово") -> 17 | D13: =COUNTIFS(#REF!,A13,#REF!,">="&TODAY()-30) -> #REF! | E13: =COUNTIFS(#REF!,A13,#REF!,"Готово") -> #REF! | F13: =COUNTIFS(#REF!,A13,#REF!,"Проверить*") -> #REF! | G13: =COUNTIFS(#REF!,A13,#REF!,"Ошибка*") -> #REF!
A14: Сыктывдинский район | B14: =COUNTIF(Источники!$C$6:$C$504,A14) -> 11 | C14: =COUNTIFS(Источники!$C$6:$C$504,A14,Источники!$M$6:$M$504,"Готово") -> 11 | D14: =COUNTIFS(#REF!,A14,#REF!,">="&TODAY()-30) -> #REF! | E14: =COUNTIFS(#REF!,A14,#REF!,"Готово") -> #REF! | F14: =COUNTIFS(#REF!,A14,#REF!,"Проверить*") -> #REF! | G14: =COUNTIFS(#REF!,A14,#REF!,"Ошибка*") -> #REF!
A15: Сыктывкар | B15: =COUNTIF(Источники!$C$6:$C$504,A15) -> 43 | C15: =COUNTIFS(Источники!$C$6:$C$504,A15,Источники!$M$6:$M$504,"Готово") -> 38 | D15: =COUNTIFS(#REF!,A15,#REF!,">="&TODAY()-30) -> #REF! | E15: =COUNTIFS(#REF!,A15,#REF!,"Готово") -> #REF! | F15: =COUNTIFS(#REF!,A15,#REF!,"Проверить*") -> #REF! | G15: =COUNTIFS(#REF!,A15,#REF!,"Ошибка*") -> #REF!
... A23: Ухта | B23: =COUNTIF(Источники!$C$6:$C$504,A23) -> 20 | C23: =COUNTIFS(Источники!$C$6:$C$504,A23,Источники!$M$6:$M$504,"Готово") -> 20 | D23: =COUNTIFS(#REF!,A23,#REF!,">="&TODAY()-30) -> #REF! | E23: =COUNTIFS(#REF!,A23,#REF!,"Готово") -> #REF! | F23: =COUNTIFS(#REF!,A23,#REF!,"Проверить*") -> #REF! | G23: =COUNTIFS(#REF!,A23,#REF!,"Ошибка*") -> #REF!
A25: Итого | B25: =SUM(B4:B23) -> 195 | C25: =SUM(C4:C23) -> 188 | D25: =SUM(D4:D23) -> #REF! | E25: =SUM(E4:E23) -> #REF! | F25: =SUM(F4:F23) -> #REF! | G25: =SUM(G4:G23) -> #REF!
